package taverncraft.WorldGeneration.Tavern;

import java.util.Random;

import net.minecraft.block.Block;
import net.minecraft.world.World;
import net.minecraft.world.gen.feature.WorldGenerator;

//check biome decorates - lemming

public class StructureDesertTavern extends WorldGenerator
{

    public StructureDesertTavern()
    {

    }
    public boolean generate (World world, Random rand, int x, int y, int z)
    {
        
        System.out.println("Desert Tavern Generating");
        
        world.setBlock(x + 0, y + 0, z + 1, Block.sandStone.blockID, 2, 2);
        world.setBlock(x + 0, y + 0, z + 2, Block.sandStone.blockID, 2, 2);
        world.setBlock(x + 0, y + 0, z + 3, Block.sandStone.blockID, 2, 2);
        world.setBlock(x + 0, y + 0, z + 4, Block.sandStone.blockID, 2, 2);
        world.setBlock(x + 0, y + 0, z + 5, Block.sandStone.blockID, 2, 2);
        world.setBlock(x + 0, y + 0, z + 6, Block.sandStone.blockID, 2, 2);
        world.setBlock(x + 0, y + 0, z + 7, Block.sandStone.blockID, 2, 2);
        world.setBlock(x + 0, y + 0, z + 8, Block.sandStone.blockID, 2, 2);
        world.setBlock(x + 0, y + 0, z + 9, Block.sandStone.blockID, 2, 2);
        world.setBlock(x + 0, y + 0, z + 10, Block.sandStone.blockID, 2, 2);
        world.setBlock(x + 0, y + 0, z + 11, Block.sandStone.blockID, 2, 2);
        world.setBlock(x + 0, y + 0, z + 12, Block.sandStone.blockID, 2, 2);
        world.setBlock(x + 0, y + 0, z + 13, Block.sandStone.blockID, 2, 2);
        world.setBlock(x + 0, y + 0, z + 14, Block.sandStone.blockID, 2, 2);
        world.setBlock(x + 0, y + 0, z + 15, Block.sandStone.blockID, 2, 2);
        world.setBlock(x + 0, y + 0, z + 16, Block.sandStone.blockID, 2, 2);
        world.setBlock(x + 0, y + 1, z + 1, Block.sandStone.blockID, 2, 2);
        world.setBlock(x + 0, y + 1, z + 2, Block.sandStone.blockID, 2, 2);
        world.setBlock(x + 0, y + 1, z + 3, Block.sandStone.blockID, 2, 2);
        world.setBlock(x + 0, y + 1, z + 4, Block.sandStone.blockID, 2, 2);
        world.setBlock(x + 0, y + 1, z + 5, Block.sandStone.blockID, 2, 2);
        world.setBlock(x + 0, y + 1, z + 6, Block.sandStone.blockID, 2, 2);
        world.setBlock(x + 0, y + 1, z + 7, Block.sandStone.blockID, 2, 2);
        world.setBlock(x + 0, y + 1, z + 8, Block.sandStone.blockID, 2, 2);
        world.setBlock(x + 0, y + 1, z + 9, Block.sandStone.blockID, 2, 2);
        world.setBlock(x + 0, y + 1, z + 10, Block.sandStone.blockID, 2, 2);
        world.setBlock(x + 0, y + 1, z + 11, Block.sandStone.blockID, 2, 2);
        world.setBlock(x + 0, y + 1, z + 12, Block.sandStone.blockID, 2, 2);
        world.setBlock(x + 0, y + 1, z + 13, Block.sandStone.blockID, 2, 2);
        world.setBlock(x + 0, y + 1, z + 14, Block.sandStone.blockID, 2, 2);
        world.setBlock(x + 0, y + 1, z + 15, Block.sandStone.blockID, 2, 2);
        world.setBlock(x + 0, y + 1, z + 16, Block.sandStone.blockID, 2, 2);
        world.setBlock(x + 0, y + 2, z + 1, Block.sandStone.blockID, 2, 2);
        world.setBlock(x + 0, y + 2, z + 2, Block.sandStone.blockID, 2, 2);
        world.setBlock(x + 0, y + 2, z + 3, Block.sandStone.blockID, 2, 2);
        world.setBlock(x + 0, y + 2, z + 4, Block.sandStone.blockID, 2, 2);
        world.setBlock(x + 0, y + 2, z + 5, Block.sandStone.blockID, 2, 2);
        world.setBlock(x + 0, y + 2, z + 6, Block.sandStone.blockID, 2, 2);
        world.setBlock(x + 0, y + 2, z + 7, Block.sandStone.blockID, 2, 2);
        world.setBlock(x + 0, y + 2, z + 8, Block.sandStone.blockID, 2, 2);
        world.setBlock(x + 0, y + 2, z + 9, Block.sandStone.blockID, 2, 2);
        world.setBlock(x + 0, y + 2, z + 10, Block.sandStone.blockID, 2, 2);
        world.setBlock(x + 0, y + 2, z + 11, Block.sandStone.blockID, 2, 2);
        world.setBlock(x + 0, y + 2, z + 12, Block.sandStone.blockID, 2, 2);
        world.setBlock(x + 0, y + 2, z + 13, Block.sandStone.blockID, 2, 2);
        world.setBlock(x + 0, y + 2, z + 14, Block.sandStone.blockID, 2, 2);
        world.setBlock(x + 0, y + 2, z + 15, Block.sandStone.blockID, 2, 2);
        world.setBlock(x + 0, y + 2, z + 16, Block.sandStone.blockID, 2, 2);
        world.setBlock(x + 0, y + 3, z + 1, Block.sandStone.blockID, 2, 2);
        world.setBlock(x + 0, y + 3, z + 2, Block.sandStone.blockID, 2, 2);
        world.setBlock(x + 0, y + 3, z + 3, Block.sandStone.blockID, 2, 2);
        world.setBlock(x + 0, y + 3, z + 4, Block.sandStone.blockID, 2, 2);
        world.setBlock(x + 0, y + 3, z + 5, Block.sandStone.blockID, 2, 2);
        world.setBlock(x + 0, y + 3, z + 6, Block.sandStone.blockID, 2, 2);
        world.setBlock(x + 0, y + 3, z + 7, Block.sandStone.blockID, 2, 2);
        world.setBlock(x + 0, y + 3, z + 8, Block.sandStone.blockID, 2, 2);
        world.setBlock(x + 0, y + 3, z + 9, Block.sandStone.blockID, 2, 2);
        world.setBlock(x + 0, y + 3, z + 10, Block.sandStone.blockID, 2, 2);
        world.setBlock(x + 0, y + 3, z + 11, Block.sandStone.blockID, 2, 2);
        world.setBlock(x + 0, y + 3, z + 12, Block.sandStone.blockID, 2, 2);
        world.setBlock(x + 0, y + 3, z + 13, Block.sandStone.blockID, 2, 2);
        world.setBlock(x + 0, y + 3, z + 14, Block.sandStone.blockID, 2, 2);
        world.setBlock(x + 0, y + 3, z + 15, Block.sandStone.blockID, 2, 2);
        world.setBlock(x + 0, y + 3, z + 16, Block.sandStone.blockID, 2, 2);
        world.setBlock(x + 0, y + 4, z + 1, Block.sandStone.blockID, 2, 2);
        world.setBlock(x + 0, y + 4, z + 2, Block.sandStone.blockID, 2, 2);
        world.setBlock(x + 0, y + 4, z + 3, Block.sandStone.blockID, 2, 2);
        world.setBlock(x + 0, y + 4, z + 4, Block.sandStone.blockID, 2, 2);
        world.setBlock(x + 0, y + 4, z + 5, Block.sandStone.blockID, 2, 2);
        world.setBlock(x + 0, y + 4, z + 6, Block.sandStone.blockID, 2, 2);
        world.setBlock(x + 0, y + 4, z + 7, Block.sandStone.blockID, 2, 2);
        world.setBlock(x + 0, y + 4, z + 8, Block.sandStone.blockID, 2, 2);
        world.setBlock(x + 0, y + 4, z + 9, Block.sandStone.blockID, 2, 2);
        world.setBlock(x + 0, y + 4, z + 10, Block.sandStone.blockID, 2, 2);
        world.setBlock(x + 0, y + 4, z + 11, Block.sandStone.blockID, 2, 2);
        world.setBlock(x + 0, y + 4, z + 12, Block.sandStone.blockID, 2, 2);
        world.setBlock(x + 0, y + 4, z + 13, Block.sandStone.blockID, 2, 2);
        world.setBlock(x + 0, y + 4, z + 14, Block.sandStone.blockID, 2, 2);
        world.setBlock(x + 0, y + 4, z + 15, Block.sandStone.blockID, 2, 2);
        world.setBlock(x + 0, y + 4, z + 16, Block.sandStone.blockID, 2, 2);
        world.setBlock(x + 0, y + 5, z + 1, Block.sandStone.blockID, 2, 2);
        world.setBlock(x + 0, y + 5, z + 2, Block.sandStone.blockID, 2, 2);
        world.setBlock(x + 0, y + 5, z + 3, Block.sandStone.blockID, 2, 2);
        world.setBlock(x + 0, y + 5, z + 4, Block.sandStone.blockID, 2, 2);
        world.setBlock(x + 0, y + 5, z + 5, Block.sandStone.blockID, 2, 2);
        world.setBlock(x + 0, y + 5, z + 6, Block.sandStone.blockID, 2, 2);
        world.setBlock(x + 0, y + 5, z + 7, Block.sandStone.blockID, 2, 2);
        world.setBlock(x + 0, y + 5, z + 8, Block.sandStone.blockID, 2, 2);
        world.setBlock(x + 0, y + 5, z + 9, Block.sandStone.blockID, 2, 2);
        world.setBlock(x + 0, y + 5, z + 10, Block.sandStone.blockID, 2, 2);
        world.setBlock(x + 0, y + 5, z + 11, Block.sandStone.blockID, 2, 2);
        world.setBlock(x + 0, y + 5, z + 12, Block.sandStone.blockID, 2, 2);
        world.setBlock(x + 0, y + 5, z + 13, Block.sandStone.blockID, 2, 2);
        world.setBlock(x + 0, y + 5, z + 14, Block.sandStone.blockID, 2, 2);
        world.setBlock(x + 0, y + 5, z + 15, Block.sandStone.blockID, 2, 2);
        world.setBlock(x + 0, y + 5, z + 16, Block.sandStone.blockID, 2, 2);
        world.setBlock(x + 0, y + 6, z + 1, Block.sandStone.blockID, 2, 2);
        world.setBlock(x + 0, y + 6, z + 2, Block.sandStone.blockID, 2, 2);
        world.setBlock(x + 0, y + 6, z + 3, Block.sandStone.blockID, 2, 2);
        world.setBlock(x + 0, y + 6, z + 4, Block.sandStone.blockID, 2, 2);
        world.setBlock(x + 0, y + 6, z + 5, Block.sandStone.blockID, 2, 2);
        world.setBlock(x + 0, y + 6, z + 6, Block.sandStone.blockID, 2, 2);
        world.setBlock(x + 0, y + 6, z + 7, Block.sandStone.blockID, 2, 2);
        world.setBlock(x + 0, y + 6, z + 8, Block.sandStone.blockID, 2, 2);
        world.setBlock(x + 0, y + 6, z + 9, Block.sandStone.blockID, 2, 2);
        world.setBlock(x + 0, y + 6, z + 10, Block.sandStone.blockID, 2, 2);
        world.setBlock(x + 0, y + 6, z + 11, Block.sandStone.blockID, 2, 2);
        world.setBlock(x + 0, y + 6, z + 12, Block.sandStone.blockID, 2, 2);
        world.setBlock(x + 0, y + 6, z + 13, Block.sandStone.blockID, 2, 2);
        world.setBlock(x + 0, y + 6, z + 14, Block.sandStone.blockID, 2, 2);
        world.setBlock(x + 0, y + 6, z + 15, Block.sandStone.blockID, 2, 2);
        world.setBlock(x + 0, y + 6, z + 16, Block.sandStone.blockID, 2, 2);
        world.setBlock(x + 0, y + 7, z + 1, Block.sandStone.blockID, 2, 2);
        world.setBlock(x + 0, y + 7, z + 2, Block.sandStone.blockID, 2, 2);
        world.setBlock(x + 0, y + 7, z + 3, Block.sandStone.blockID, 2, 2);
        world.setBlock(x + 0, y + 7, z + 4, Block.sandStone.blockID, 2, 2);
        world.setBlock(x + 0, y + 7, z + 5, Block.sandStone.blockID, 2, 2);
        world.setBlock(x + 0, y + 7, z + 6, Block.sandStone.blockID, 2, 2);
        world.setBlock(x + 0, y + 7, z + 7, Block.sandStone.blockID, 2, 2);
        world.setBlock(x + 0, y + 7, z + 8, Block.sandStone.blockID, 2, 2);
        world.setBlock(x + 0, y + 7, z + 9, Block.sandStone.blockID, 2, 2);
        world.setBlock(x + 0, y + 7, z + 10, Block.sandStone.blockID, 2, 2);
        world.setBlock(x + 0, y + 7, z + 11, Block.sandStone.blockID, 2, 2);
        world.setBlock(x + 0, y + 7, z + 12, Block.sandStone.blockID, 2, 2);
        world.setBlock(x + 0, y + 7, z + 13, Block.sandStone.blockID, 2, 2);
        world.setBlock(x + 0, y + 7, z + 14, Block.sandStone.blockID, 2, 2);
        world.setBlock(x + 0, y + 7, z + 15, Block.sandStone.blockID, 2, 2);
        world.setBlock(x + 0, y + 7, z + 16, Block.sandStone.blockID, 2, 2);
        world.setBlock(x + 0, y + 8, z + 1, Block.sandStone.blockID, 2, 2);
        world.setBlock(x + 0, y + 8, z + 2, Block.sandStone.blockID, 2, 2);
        world.setBlock(x + 0, y + 8, z + 3, Block.sandStone.blockID, 2, 2);
        world.setBlock(x + 0, y + 8, z + 4, Block.sandStone.blockID, 2, 2);
        world.setBlock(x + 0, y + 8, z + 5, Block.sandStone.blockID, 2, 2);
        world.setBlock(x + 0, y + 8, z + 6, Block.sandStone.blockID, 2, 2);
        world.setBlock(x + 0, y + 8, z + 7, Block.sandStone.blockID, 2, 2);
        world.setBlock(x + 0, y + 8, z + 8, Block.sandStone.blockID, 2, 2);
        world.setBlock(x + 0, y + 8, z + 9, Block.sandStone.blockID, 2, 2);
        world.setBlock(x + 0, y + 8, z + 10, Block.sandStone.blockID, 2, 2);
        world.setBlock(x + 0, y + 8, z + 11, Block.sandStone.blockID, 2, 2);
        world.setBlock(x + 0, y + 8, z + 12, Block.sandStone.blockID, 2, 2);
        world.setBlock(x + 0, y + 8, z + 13, Block.sandStone.blockID, 2, 2);
        world.setBlock(x + 0, y + 8, z + 14, Block.sandStone.blockID, 2, 2);
        world.setBlock(x + 0, y + 8, z + 15, Block.sandStone.blockID, 2, 2);
        world.setBlock(x + 0, y + 8, z + 16, Block.sandStone.blockID, 2, 2);
        world.setBlock(x + 0, y + 9, z + 1, Block.sandStone.blockID, 2, 2);
        world.setBlock(x + 0, y + 9, z + 2, Block.sandStone.blockID, 2, 2);
        world.setBlock(x + 0, y + 9, z + 3, Block.sandStone.blockID, 2, 2);
        world.setBlock(x + 0, y + 9, z + 4, Block.sandStone.blockID, 2, 2);
        world.setBlock(x + 0, y + 9, z + 5, Block.sandStone.blockID, 2, 2);
        world.setBlock(x + 0, y + 9, z + 6, Block.sandStone.blockID, 2, 2);
        world.setBlock(x + 0, y + 9, z + 7, Block.sandStone.blockID, 2, 2);
        world.setBlock(x + 0, y + 9, z + 8, Block.sandStone.blockID, 2, 2);
        world.setBlock(x + 0, y + 9, z + 9, Block.sandStone.blockID, 2, 2);
        world.setBlock(x + 0, y + 9, z + 10, Block.sandStone.blockID, 2, 2);
        world.setBlock(x + 0, y + 9, z + 11, Block.sandStone.blockID, 2, 2);
        world.setBlock(x + 0, y + 9, z + 12, Block.sandStone.blockID, 2, 2);
        world.setBlock(x + 0, y + 9, z + 13, Block.sandStone.blockID, 2, 2);
        world.setBlock(x + 0, y + 9, z + 14, Block.sandStone.blockID, 2, 2);
        world.setBlock(x + 0, y + 9, z + 15, Block.sandStone.blockID, 2, 2);
        world.setBlock(x + 0, y + 9, z + 16, Block.sandStone.blockID, 2, 2);
        world.setBlock(x + 0, y + 10, z + 1, Block.sandStone.blockID, 2, 2);
        world.setBlock(x + 0, y + 10, z + 2, Block.planks.blockID, 2, 2);
        world.setBlock(x + 0, y + 10, z + 3, Block.planks.blockID, 2, 2);
        world.setBlock(x + 0, y + 10, z + 4, Block.planks.blockID, 2, 2);
        world.setBlock(x + 0, y + 10, z + 5, Block.planks.blockID, 2, 2);
        world.setBlock(x + 0, y + 10, z + 6, Block.planks.blockID, 2, 2);
        world.setBlock(x + 0, y + 10, z + 7, Block.planks.blockID, 2, 2);
        world.setBlock(x + 0, y + 10, z + 8, Block.planks.blockID, 2, 2);
        world.setBlock(x + 0, y + 10, z + 9, Block.planks.blockID, 2, 2);
        world.setBlock(x + 0, y + 10, z + 10, Block.planks.blockID, 2, 2);
        world.setBlock(x + 0, y + 10, z + 11, Block.planks.blockID, 2, 2);
        world.setBlock(x + 0, y + 10, z + 12, Block.planks.blockID, 2, 2);
        world.setBlock(x + 0, y + 10, z + 13, Block.planks.blockID, 2, 2);
        world.setBlock(x + 0, y + 10, z + 14, Block.planks.blockID, 2, 2);
        world.setBlock(x + 0, y + 10, z + 15, Block.planks.blockID, 2, 2);
        world.setBlock(x + 0, y + 10, z + 16, Block.sandStone.blockID, 2, 2);
        world.setBlock(x + 0, y + 11, z + 1, Block.sandStone.blockID, 2, 2);
        world.setBlock(x + 0, y + 11, z + 2, Block.planks.blockID, 2, 2);
        world.setBlock(x + 0, y + 11, z + 3, Block.planks.blockID, 2, 2);
        world.setBlock(x + 0, y + 11, z + 4, Block.planks.blockID, 2, 2);
        world.setBlock(x + 0, y + 11, z + 5, Block.planks.blockID, 2, 2);
        world.setBlock(x + 0, y + 11, z + 6, Block.planks.blockID, 2, 2);
        world.setBlock(x + 0, y + 11, z + 7, Block.planks.blockID, 2, 2);
        world.setBlock(x + 0, y + 11, z + 8, Block.planks.blockID, 2, 2);
        world.setBlock(x + 0, y + 11, z + 9, Block.planks.blockID, 2, 2);
        world.setBlock(x + 0, y + 11, z + 10, Block.planks.blockID, 2, 2);
        world.setBlock(x + 0, y + 11, z + 11, Block.planks.blockID, 2, 2);
        world.setBlock(x + 0, y + 11, z + 12, Block.planks.blockID, 2, 2);
        world.setBlock(x + 0, y + 11, z + 13, Block.planks.blockID, 2, 2);
        world.setBlock(x + 0, y + 11, z + 14, Block.planks.blockID, 2, 2);
        world.setBlock(x + 0, y + 11, z + 15, Block.planks.blockID, 2, 2);
        world.setBlock(x + 0, y + 11, z + 16, Block.sandStone.blockID, 2, 2);
        world.setBlock(x + 0, y + 12, z + 1, Block.sandStone.blockID, 2, 2);
        world.setBlock(x + 0, y + 12, z + 2, Block.planks.blockID, 2, 2);
        world.setBlock(x + 0, y + 12, z + 3, Block.planks.blockID, 2, 2);
        world.setBlock(x + 0, y + 12, z + 4, Block.planks.blockID, 2, 2);
        world.setBlock(x + 0, y + 12, z + 5, Block.planks.blockID, 2, 2);
        world.setBlock(x + 0, y + 12, z + 6, Block.planks.blockID, 2, 2);
        world.setBlock(x + 0, y + 12, z + 7, Block.planks.blockID, 2, 2);
        world.setBlock(x + 0, y + 12, z + 8, Block.planks.blockID, 2, 2);
        world.setBlock(x + 0, y + 12, z + 9, Block.planks.blockID, 2, 2);
        world.setBlock(x + 0, y + 12, z + 10, Block.planks.blockID, 2, 2);
        world.setBlock(x + 0, y + 12, z + 11, Block.planks.blockID, 2, 2);
        world.setBlock(x + 0, y + 12, z + 12, Block.planks.blockID, 2, 2);
        world.setBlock(x + 0, y + 12, z + 13, Block.planks.blockID, 2, 2);
        world.setBlock(x + 0, y + 12, z + 14, Block.planks.blockID, 2, 2);
        world.setBlock(x + 0, y + 12, z + 15, Block.planks.blockID, 2, 2);
        world.setBlock(x + 0, y + 12, z + 16, Block.sandStone.blockID, 2, 2);
        world.setBlock(x + 0, y + 13, z + 1, Block.sandStone.blockID, 2, 2);
        world.setBlock(x + 0, y + 13, z + 2, Block.planks.blockID, 2, 2);
        world.setBlock(x + 0, y + 13, z + 3, Block.planks.blockID, 2, 2);
        world.setBlock(x + 0, y + 13, z + 4, Block.planks.blockID, 2, 2);
        world.setBlock(x + 0, y + 13, z + 5, Block.planks.blockID, 2, 2);
        world.setBlock(x + 0, y + 13, z + 6, Block.planks.blockID, 2, 2);
        world.setBlock(x + 0, y + 13, z + 7, Block.planks.blockID, 2, 2);
        world.setBlock(x + 0, y + 13, z + 8, Block.planks.blockID, 2, 2);
        world.setBlock(x + 0, y + 13, z + 9, Block.planks.blockID, 2, 2);
        world.setBlock(x + 0, y + 13, z + 10, Block.planks.blockID, 2, 2);
        world.setBlock(x + 0, y + 13, z + 11, Block.planks.blockID, 2, 2);
        world.setBlock(x + 0, y + 13, z + 12, Block.planks.blockID, 2, 2);
        world.setBlock(x + 0, y + 13, z + 13, Block.planks.blockID, 2, 2);
        world.setBlock(x + 0, y + 13, z + 14, Block.planks.blockID, 2, 2);
        world.setBlock(x + 0, y + 13, z + 15, Block.planks.blockID, 2, 2);
        world.setBlock(x + 0, y + 13, z + 16, Block.sandStone.blockID, 2, 2);
        world.setBlock(x + 0, y + 14, z + 0, 0);
        world.setBlock(x + 0, y + 14, z + 1, Block.sandStone.blockID, 2, 2);
        world.setBlock(x + 0, y + 14, z + 2, Block.sandStone.blockID, 2, 2);
        world.setBlock(x + 0, y + 14, z + 3, Block.sandStone.blockID, 2, 2);
        world.setBlock(x + 0, y + 14, z + 4, Block.sandStone.blockID, 2, 2);
        world.setBlock(x + 0, y + 14, z + 5, Block.sandStone.blockID, 2, 2);
        world.setBlock(x + 0, y + 14, z + 6, Block.sandStone.blockID, 2, 2);
        world.setBlock(x + 0, y + 14, z + 7, Block.sandStone.blockID, 2, 2);
        world.setBlock(x + 0, y + 14, z + 8, Block.sandStone.blockID, 2, 2);
        world.setBlock(x + 0, y + 14, z + 9, Block.sandStone.blockID, 2, 2);
        world.setBlock(x + 0, y + 14, z + 10, Block.sandStone.blockID, 2, 2);
        world.setBlock(x + 0, y + 14, z + 11, Block.sandStone.blockID, 2, 2);
        world.setBlock(x + 0, y + 14, z + 12, Block.sandStone.blockID, 2, 2);
        world.setBlock(x + 0, y + 14, z + 13, Block.sandStone.blockID, 2, 2);
        world.setBlock(x + 0, y + 14, z + 14, Block.sandStone.blockID, 2, 2);
        world.setBlock(x + 0, y + 14, z + 15, Block.sandStone.blockID, 2, 2);
        world.setBlock(x + 0, y + 14, z + 16, Block.sandStone.blockID, 2, 2);
        world.setBlock(x + 0, y + 14, z + 17, 0);
        world.setBlock(x + 0, y + 15, z + 0, 0);
        world.setBlock(x + 0, y + 15, z + 1, Block.sandStone.blockID, 2, 2);
        world.setBlock(x + 0, y + 15, z + 2, Block.sandStone.blockID, 2, 2);
        world.setBlock(x + 0, y + 15, z + 3, Block.sandStone.blockID, 2, 2);
        world.setBlock(x + 0, y + 15, z + 4, Block.sandStone.blockID, 2, 2);
        world.setBlock(x + 0, y + 15, z + 5, Block.sandStone.blockID, 2, 2);
        world.setBlock(x + 0, y + 15, z + 6, Block.sandStone.blockID, 2, 2);
        world.setBlock(x + 0, y + 15, z + 7, Block.sandStone.blockID, 2, 2);
        world.setBlock(x + 0, y + 15, z + 8, Block.sandStone.blockID, 2, 2);
        world.setBlock(x + 0, y + 15, z + 9, Block.sandStone.blockID, 2, 2);
        world.setBlock(x + 0, y + 15, z + 10, Block.sandStone.blockID, 2, 2);
        world.setBlock(x + 0, y + 15, z + 11, Block.sandStone.blockID, 2, 2);
        world.setBlock(x + 0, y + 15, z + 12, Block.sandStone.blockID, 2, 2);
        world.setBlock(x + 0, y + 15, z + 13, Block.sandStone.blockID, 2, 2);
        world.setBlock(x + 0, y + 15, z + 14, Block.sandStone.blockID, 2, 2);
        world.setBlock(x + 0, y + 15, z + 15, Block.sandStone.blockID, 2, 2);
        world.setBlock(x + 0, y + 15, z + 16, Block.sandStone.blockID, 2, 2);
        world.setBlock(x + 0, y + 15, z + 17, 0);
        world.setBlock(x + 0, y + 16, z + 0, 0);
        world.setBlock(x + 0, y + 16, z + 1, Block.sandStone.blockID, 2, 2);
        world.setBlock(x + 0, y + 16, z + 2, Block.sandStone.blockID, 2, 2);
        world.setBlock(x + 0, y + 16, z + 3, Block.sandStone.blockID, 2, 2);
        world.setBlock(x + 0, y + 16, z + 4, Block.sandStone.blockID, 2, 2);
        world.setBlock(x + 0, y + 16, z + 5, Block.sandStone.blockID, 2, 2);
        world.setBlock(x + 0, y + 16, z + 6, Block.sandStone.blockID, 2, 2);
        world.setBlock(x + 0, y + 16, z + 7, Block.sandStone.blockID, 2, 2);
        world.setBlock(x + 0, y + 16, z + 8, Block.sandStone.blockID, 2, 2);
        world.setBlock(x + 0, y + 16, z + 9, Block.sandStone.blockID, 2, 2);
        world.setBlock(x + 0, y + 16, z + 10, Block.sandStone.blockID, 2, 2);
        world.setBlock(x + 0, y + 16, z + 11, Block.sandStone.blockID, 2, 2);
        world.setBlock(x + 0, y + 16, z + 12, Block.sandStone.blockID, 2, 2);
        world.setBlock(x + 0, y + 16, z + 13, Block.sandStone.blockID, 2, 2);
        world.setBlock(x + 0, y + 16, z + 14, Block.sandStone.blockID, 2, 2);
        world.setBlock(x + 0, y + 16, z + 15, Block.sandStone.blockID, 2, 2);
        world.setBlock(x + 0, y + 16, z + 16, Block.sandStone.blockID, 2, 2);
        world.setBlock(x + 0, y + 16, z + 17, 0);
        world.setBlock(x + 0, y + 17, z + 0, 0);
        world.setBlock(x + 0, y + 17, z + 1, Block.sandStone.blockID, 2, 2);
        world.setBlock(x + 0, y + 17, z + 2, Block.sandStone.blockID, 2, 2);
        world.setBlock(x + 0, y + 17, z + 3, Block.planks.blockID, 2, 2);
        world.setBlock(x + 0, y + 17, z + 4, Block.planks.blockID, 2, 2);
        world.setBlock(x + 0, y + 17, z + 5, Block.planks.blockID, 2, 2);
        world.setBlock(x + 0, y + 17, z + 6, Block.planks.blockID, 2, 2);
        world.setBlock(x + 0, y + 17, z + 7, Block.thinGlass.blockID, 0, 2);
        world.setBlock(x + 0, y + 17, z + 8, Block.thinGlass.blockID, 0, 2);
        world.setBlock(x + 0, y + 17, z + 9, Block.thinGlass.blockID, 0, 2);
        world.setBlock(x + 0, y + 17, z + 10, Block.thinGlass.blockID, 0, 2);
        world.setBlock(x + 0, y + 17, z + 11, Block.planks.blockID, 2, 2);
        world.setBlock(x + 0, y + 17, z + 12, Block.planks.blockID, 2, 2);
        world.setBlock(x + 0, y + 17, z + 13, Block.planks.blockID, 2, 2);
        world.setBlock(x + 0, y + 17, z + 14, Block.planks.blockID, 2, 2);
        world.setBlock(x + 0, y + 17, z + 15, Block.sandStone.blockID, 2, 2);
        world.setBlock(x + 0, y + 17, z + 16, Block.sandStone.blockID, 2, 2);
        world.setBlock(x + 0, y + 17, z + 17, 0);
        world.setBlock(x + 0, y + 18, z + 0, 0);
        world.setBlock(x + 0, y + 18, z + 1, Block.sandStone.blockID, 2, 2);
        world.setBlock(x + 0, y + 18, z + 2, Block.sandStone.blockID, 2, 2);
        world.setBlock(x + 0, y + 18, z + 3, Block.planks.blockID, 2, 2);
        world.setBlock(x + 0, y + 18, z + 4, Block.planks.blockID, 2, 2);
        world.setBlock(x + 0, y + 18, z + 5, Block.thinGlass.blockID, 0, 2);
        world.setBlock(x + 0, y + 18, z + 6, Block.thinGlass.blockID, 0, 2);
        world.setBlock(x + 0, y + 18, z + 7, Block.thinGlass.blockID, 0, 2);
        world.setBlock(x + 0, y + 18, z + 8, Block.thinGlass.blockID, 0, 2);
        world.setBlock(x + 0, y + 18, z + 9, Block.thinGlass.blockID, 0, 2);
        world.setBlock(x + 0, y + 18, z + 10, Block.thinGlass.blockID, 0, 2);
        world.setBlock(x + 0, y + 18, z + 11, Block.thinGlass.blockID, 0, 2);
        world.setBlock(x + 0, y + 18, z + 12, Block.thinGlass.blockID, 0, 2);
        world.setBlock(x + 0, y + 18, z + 13, Block.planks.blockID, 2, 2);
        world.setBlock(x + 0, y + 18, z + 14, Block.planks.blockID, 2, 2);
        world.setBlock(x + 0, y + 18, z + 15, Block.sandStone.blockID, 2, 2);
        world.setBlock(x + 0, y + 18, z + 16, Block.sandStone.blockID, 2, 2);
        world.setBlock(x + 0, y + 18, z + 17, 0);
        world.setBlock(x + 0, y + 19, z + 0, Block.stairsSandStone.blockID, 2, 2);
        world.setBlock(x + 0, y + 19, z + 1, Block.sandStone.blockID, 2, 2);
        world.setBlock(x + 0, y + 19, z + 2, Block.sandStone.blockID, 2, 2);
        world.setBlock(x + 0, y + 19, z + 3, Block.planks.blockID, 2, 2);
        world.setBlock(x + 0, y + 19, z + 4, Block.planks.blockID, 2, 2);
        world.setBlock(x + 0, y + 19, z + 5, Block.planks.blockID, 2, 2);
        world.setBlock(x + 0, y + 19, z + 6, Block.planks.blockID, 2, 2);
        world.setBlock(x + 0, y + 19, z + 7, Block.thinGlass.blockID, 0, 2);
        world.setBlock(x + 0, y + 19, z + 8, Block.thinGlass.blockID, 0, 2);
        world.setBlock(x + 0, y + 19, z + 9, Block.thinGlass.blockID, 0, 2);
        world.setBlock(x + 0, y + 19, z + 10, Block.thinGlass.blockID, 0, 2);
        world.setBlock(x + 0, y + 19, z + 11, Block.planks.blockID, 2, 2);
        world.setBlock(x + 0, y + 19, z + 12, Block.planks.blockID, 2, 2);
        world.setBlock(x + 0, y + 19, z + 13, Block.planks.blockID, 2, 2);
        world.setBlock(x + 0, y + 19, z + 14, Block.planks.blockID, 2, 2);
        world.setBlock(x + 0, y + 19, z + 15, Block.sandStone.blockID, 2, 2);
        world.setBlock(x + 0, y + 19, z + 16, Block.sandStone.blockID, 2, 2);
        world.setBlock(x + 0, y + 19, z + 17, Block.stairsSandStone.blockID, 3, 2);
        world.setBlock(x + 0, y + 20, z + 0, 0);
        world.setBlock(x + 0, y + 20, z + 1, Block.stairsSandStone.blockID, 2, 2);
        world.setBlock(x + 0, y + 20, z + 2, Block.sandStone.blockID, 2, 2);
        world.setBlock(x + 0, y + 20, z + 3, Block.sandStone.blockID, 2, 2);
        world.setBlock(x + 0, y + 20, z + 4, Block.sandStone.blockID, 2, 2);
        world.setBlock(x + 0, y + 20, z + 5, Block.sandStone.blockID, 2, 2);
        world.setBlock(x + 0, y + 20, z + 6, Block.sandStone.blockID, 2, 2);
        world.setBlock(x + 0, y + 20, z + 7, Block.sandStone.blockID, 2, 2);
        world.setBlock(x + 0, y + 20, z + 8, Block.sandStone.blockID, 2, 2);
        world.setBlock(x + 0, y + 20, z + 9, Block.sandStone.blockID, 2, 2);
        world.setBlock(x + 0, y + 20, z + 10, Block.sandStone.blockID, 2, 2);
        world.setBlock(x + 0, y + 20, z + 11, Block.sandStone.blockID, 2, 2);
        world.setBlock(x + 0, y + 20, z + 12, Block.sandStone.blockID, 2, 2);
        world.setBlock(x + 0, y + 20, z + 13, Block.sandStone.blockID, 2, 2);
        world.setBlock(x + 0, y + 20, z + 14, Block.sandStone.blockID, 2, 2);
        world.setBlock(x + 0, y + 20, z + 15, Block.sandStone.blockID, 2, 2);
        world.setBlock(x + 0, y + 20, z + 16, Block.stairsSandStone.blockID, 3, 2);
        world.setBlock(x + 0, y + 20, z + 17, 0);
        world.setBlock(x + 0, y + 21, z + 0, 0);
        world.setBlock(x + 0, y + 21, z + 1, 0);
        world.setBlock(x + 0, y + 21, z + 2, Block.stairsSandStone.blockID, 2, 2);
        world.setBlock(x + 0, y + 21, z + 3, Block.sandStone.blockID, 2, 2);
        world.setBlock(x + 0, y + 21, z + 4, Block.sandStone.blockID, 2, 2);
        world.setBlock(x + 0, y + 21, z + 5, Block.sandStone.blockID, 2, 2);
        world.setBlock(x + 0, y + 21, z + 6, Block.sandStone.blockID, 2, 2);
        world.setBlock(x + 0, y + 21, z + 7, Block.sandStone.blockID, 2, 2);
        world.setBlock(x + 0, y + 21, z + 8, Block.sandStone.blockID, 2, 2);
        world.setBlock(x + 0, y + 21, z + 9, Block.sandStone.blockID, 2, 2);
        world.setBlock(x + 0, y + 21, z + 10, Block.sandStone.blockID, 2, 2);
        world.setBlock(x + 0, y + 21, z + 11, Block.sandStone.blockID, 2, 2);
        world.setBlock(x + 0, y + 21, z + 12, Block.sandStone.blockID, 2, 2);
        world.setBlock(x + 0, y + 21, z + 13, Block.sandStone.blockID, 2, 2);
        world.setBlock(x + 0, y + 21, z + 14, Block.sandStone.blockID, 2, 2);
        world.setBlock(x + 0, y + 21, z + 15, Block.stairsSandStone.blockID, 3, 2);
        world.setBlock(x + 0, y + 21, z + 16, 0);
        world.setBlock(x + 0, y + 21, z + 17, 0);
        world.setBlock(x + 0, y + 22, z + 0, 0);
        world.setBlock(x + 0, y + 22, z + 1, 0);
        world.setBlock(x + 0, y + 22, z + 2, 0);
        world.setBlock(x + 0, y + 22, z + 3, Block.stairsSandStone.blockID, 2, 2);
        world.setBlock(x + 0, y + 22, z + 4, Block.sandStone.blockID, 2, 2);
        world.setBlock(x + 0, y + 22, z + 5, Block.sandStone.blockID, 2, 2);
        world.setBlock(x + 0, y + 22, z + 6, Block.sandStone.blockID, 2, 2);
        world.setBlock(x + 0, y + 22, z + 7, Block.sandStone.blockID, 2, 2);
        world.setBlock(x + 0, y + 22, z + 8, Block.sandStone.blockID, 2, 2);
        world.setBlock(x + 0, y + 22, z + 9, Block.sandStone.blockID, 2, 2);
        world.setBlock(x + 0, y + 22, z + 10, Block.sandStone.blockID, 2, 2);
        world.setBlock(x + 0, y + 22, z + 11, Block.sandStone.blockID, 2, 2);
        world.setBlock(x + 0, y + 22, z + 12, Block.sandStone.blockID, 2, 2);
        world.setBlock(x + 0, y + 22, z + 13, Block.sandStone.blockID, 2, 2);
        world.setBlock(x + 0, y + 22, z + 14, Block.stairsSandStone.blockID, 3, 2);
        world.setBlock(x + 0, y + 22, z + 15, 0);
        world.setBlock(x + 0, y + 22, z + 16, 0);
        world.setBlock(x + 0, y + 22, z + 17, 0);
        world.setBlock(x + 0, y + 23, z + 0, 0);
        world.setBlock(x + 0, y + 23, z + 1, 0);
        world.setBlock(x + 0, y + 23, z + 2, 0);
        world.setBlock(x + 0, y + 23, z + 3, 0);
        world.setBlock(x + 0, y + 23, z + 4, Block.stairsSandStone.blockID, 2, 2);
        world.setBlock(x + 0, y + 23, z + 5, Block.sandStone.blockID, 2, 2);
        world.setBlock(x + 0, y + 23, z + 6, Block.sandStone.blockID, 2, 2);
        world.setBlock(x + 0, y + 23, z + 7, Block.sandStone.blockID, 2, 2);
        world.setBlock(x + 0, y + 23, z + 8, Block.sandStone.blockID, 2, 2);
        world.setBlock(x + 0, y + 23, z + 9, Block.sandStone.blockID, 2, 2);
        world.setBlock(x + 0, y + 23, z + 10, Block.sandStone.blockID, 2, 2);
        world.setBlock(x + 0, y + 23, z + 11, Block.sandStone.blockID, 2, 2);
        world.setBlock(x + 0, y + 23, z + 12, Block.sandStone.blockID, 2, 2);
        world.setBlock(x + 0, y + 23, z + 13, Block.stairsSandStone.blockID, 3, 2);
        world.setBlock(x + 0, y + 23, z + 14, 0);
        world.setBlock(x + 0, y + 23, z + 15, 0);
        world.setBlock(x + 0, y + 23, z + 16, 0);
        world.setBlock(x + 0, y + 23, z + 17, 0);
        world.setBlock(x + 0, y + 24, z + 0, 0);
        world.setBlock(x + 0, y + 24, z + 1, 0);
        world.setBlock(x + 0, y + 24, z + 2, 0);
        world.setBlock(x + 0, y + 24, z + 3, 0);
        world.setBlock(x + 0, y + 24, z + 4, 0);
        world.setBlock(x + 0, y + 24, z + 5, Block.stairsSandStone.blockID, 2, 2);
        world.setBlock(x + 0, y + 24, z + 6, Block.sandStone.blockID, 0, 2);
        world.setBlock(x + 0, y + 24, z + 7, Block.sandStone.blockID, 0, 2);
        world.setBlock(x + 0, y + 24, z + 8, Block.sandStone.blockID, 0, 2);
        world.setBlock(x + 0, y + 24, z + 9, Block.sandStone.blockID, 0, 2);
        world.setBlock(x + 0, y + 24, z + 10, Block.sandStone.blockID, 0, 2);
        world.setBlock(x + 0, y + 24, z + 11, Block.sandStone.blockID, 0, 2);
        world.setBlock(x + 0, y + 24, z + 12, Block.stairsSandStone.blockID, 3, 2);
        world.setBlock(x + 0, y + 24, z + 13, 0);
        world.setBlock(x + 0, y + 24, z + 14, 0);
        world.setBlock(x + 0, y + 24, z + 15, 0);
        world.setBlock(x + 0, y + 24, z + 16, 0);
        world.setBlock(x + 0, y + 24, z + 17, 0);
        world.setBlock(x + 0, y + 25, z + 0, 0);
        world.setBlock(x + 0, y + 25, z + 1, 0);
        world.setBlock(x + 0, y + 25, z + 2, 0);
        world.setBlock(x + 0, y + 25, z + 3, 0);
        world.setBlock(x + 0, y + 25, z + 4, 0);
        world.setBlock(x + 0, y + 25, z + 5, 0);
        world.setBlock(x + 0, y + 25, z + 6, Block.stoneSingleSlab.blockID, 1, 2);
        world.setBlock(x + 0, y + 25, z + 7, Block.stoneSingleSlab.blockID, 1, 2);
        world.setBlock(x + 0, y + 25, z + 8, Block.stoneSingleSlab.blockID, 1, 2);
        world.setBlock(x + 0, y + 25, z + 9, Block.stoneSingleSlab.blockID, 1, 2);
        world.setBlock(x + 0, y + 25, z + 10, Block.stoneSingleSlab.blockID, 1, 2);
        world.setBlock(x + 0, y + 25, z + 11, Block.stoneSingleSlab.blockID, 1, 2);
        world.setBlock(x + 0, y + 25, z + 12, 0);
        world.setBlock(x + 0, y + 25, z + 13, 0);
        world.setBlock(x + 0, y + 25, z + 14, 0);
        world.setBlock(x + 0, y + 25, z + 15, 0);
        world.setBlock(x + 0, y + 25, z + 16, 0);
        world.setBlock(x + 0, y + 25, z + 17, 0);
        world.setBlock(x + 1, y + 0, z + 1, Block.sandStone.blockID, 2, 2);
        world.setBlock(x + 1, y + 0, z + 2, Block.stone.blockID, 0, 2);
        world.setBlock(x + 1, y + 0, z + 3, Block.stainedClay.blockID, 9, 2);
        world.setBlock(x + 1, y + 0, z + 4, Block.stainedClay.blockID, 9, 2);
        world.setBlock(x + 1, y + 0, z + 5, Block.stainedClay.blockID, 9, 2);
        world.setBlock(x + 1, y + 0, z + 6, Block.stainedClay.blockID, 9, 2);
        world.setBlock(x + 1, y + 0, z + 7, Block.stainedClay.blockID, 9, 2);
        world.setBlock(x + 1, y + 0, z + 8, Block.stainedClay.blockID, 9, 2);
        world.setBlock(x + 1, y + 0, z + 9, Block.stainedClay.blockID, 9, 2);
        world.setBlock(x + 1, y + 0, z + 10, Block.stainedClay.blockID, 9, 2);
        world.setBlock(x + 1, y + 0, z + 11, Block.stainedClay.blockID, 9, 2);
        world.setBlock(x + 1, y + 0, z + 12, Block.stainedClay.blockID, 9, 2);
        world.setBlock(x + 1, y + 0, z + 13, Block.stainedClay.blockID, 9, 2);
        world.setBlock(x + 1, y + 0, z + 14, Block.stainedClay.blockID, 9, 2);
        world.setBlock(x + 1, y + 0, z + 15, Block.stainedClay.blockID, 9, 2);
        world.setBlock(x + 1, y + 0, z + 16, Block.sandStone.blockID, 2, 2);
        world.setBlock(x + 1, y + 1, z + 1, Block.sandStone.blockID, 2, 2);
        world.setBlock(x + 1, y + 1, z + 2, Block.sandStone.blockID, 2, 2);
        world.setBlock(x + 1, y + 1, z + 3, 0);
        world.setBlock(x + 1, y + 1, z + 4, 0);
        world.setBlock(x + 1, y + 1, z + 5, 0);
        world.setBlock(x + 1, y + 1, z + 6, 0);
        world.setBlock(x + 1, y + 1, z + 7, 0);
        world.setBlock(x + 1, y + 1, z + 8, 0);
        world.setBlock(x + 1, y + 1, z + 9, 0);
        world.setBlock(x + 1, y + 1, z + 10, 0);
        world.setBlock(x + 1, y + 1, z + 11, 0);
        world.setBlock(x + 1, y + 1, z + 12, 0);
        world.setBlock(x + 1, y + 1, z + 13, 0);
        world.setBlock(x + 1, y + 1, z + 14, 0);
        world.setBlock(x + 1, y + 1, z + 15, 0);
        world.setBlock(x + 1, y + 1, z + 16, Block.sandStone.blockID, 2, 2);
        world.setBlock(x + 1, y + 2, z + 1, Block.sandStone.blockID, 2, 2);
        world.setBlock(x + 1, y + 2, z + 2, Block.sandStone.blockID, 2, 2);
        world.setBlock(x + 1, y + 2, z + 3, 0);
        world.setBlock(x + 1, y + 2, z + 4, 0);
        world.setBlock(x + 1, y + 2, z + 5, 0);
        world.setBlock(x + 1, y + 2, z + 6, 0);
        world.setBlock(x + 1, y + 2, z + 7, 0);
        world.setBlock(x + 1, y + 2, z + 8, 0);
        world.setBlock(x + 1, y + 2, z + 9, 0);
        world.setBlock(x + 1, y + 2, z + 10, 0);
        world.setBlock(x + 1, y + 2, z + 11, 0);
        world.setBlock(x + 1, y + 2, z + 12, 0);
        world.setBlock(x + 1, y + 2, z + 13, 0);
        world.setBlock(x + 1, y + 2, z + 14, 0);
        world.setBlock(x + 1, y + 2, z + 15, 0);
        world.setBlock(x + 1, y + 2, z + 16, Block.sandStone.blockID, 2, 2);
        world.setBlock(x + 1, y + 3, z + 1, Block.sandStone.blockID, 2, 2);
        world.setBlock(x + 1, y + 3, z + 2, Block.sandStone.blockID, 2, 2);
        world.setBlock(x + 1, y + 3, z + 4, 0);
        world.setBlock(x + 1, y + 3, z + 5, 0);
        world.setBlock(x + 1, y + 3, z + 6, 0);
        world.setBlock(x + 1, y + 3, z + 7, 0);
        world.setBlock(x + 1, y + 3, z + 8, 0);
        world.setBlock(x + 1, y + 3, z + 9, 0);
        world.setBlock(x + 1, y + 3, z + 11, 0);
        world.setBlock(x + 1, y + 3, z + 12, 0);
        world.setBlock(x + 1, y + 3, z + 13, 0);
        world.setBlock(x + 1, y + 3, z + 14, 0);
        world.setBlock(x + 1, y + 3, z + 16, Block.sandStone.blockID, 2, 2);
        world.setBlock(x + 1, y + 4, z + 1, Block.sandStone.blockID, 2, 2);
        world.setBlock(x + 1, y + 4, z + 2, Block.sandStone.blockID, 2, 2);
        world.setBlock(x + 1, y + 4, z + 3, Block.glass.blockID, 0, 2);
        world.setBlock(x + 1, y + 4, z + 4, Block.glass.blockID, 0, 2);
        world.setBlock(x + 1, y + 4, z + 5, Block.glass.blockID, 0, 2);
        world.setBlock(x + 1, y + 4, z + 6, Block.glass.blockID, 0, 2);
        world.setBlock(x + 1, y + 4, z + 7, Block.glass.blockID, 0, 2);
        world.setBlock(x + 1, y + 4, z + 8, Block.glass.blockID, 0, 2);
        world.setBlock(x + 1, y + 4, z + 9, Block.glass.blockID, 0, 2);
        world.setBlock(x + 1, y + 4, z + 10, Block.glass.blockID, 0, 2);
        world.setBlock(x + 1, y + 4, z + 11, Block.glass.blockID, 0, 2);
        world.setBlock(x + 1, y + 4, z + 12, Block.glass.blockID, 0, 2);
        world.setBlock(x + 1, y + 4, z + 13, Block.glass.blockID, 0, 2);
        world.setBlock(x + 1, y + 4, z + 14, Block.glass.blockID, 0, 2);
        world.setBlock(x + 1, y + 4, z + 15, Block.glass.blockID, 0, 2);
        world.setBlock(x + 1, y + 4, z + 16, Block.sandStone.blockID, 2, 2);
        world.setBlock(x + 1, y + 5, z + 1, Block.sandStone.blockID, 2, 2);
        world.setBlock(x + 1, y + 5, z + 2, Block.sandStone.blockID, 2, 2);
        world.setBlock(x + 1, y + 5, z + 3, 0);
        world.setBlock(x + 1, y + 5, z + 4, 0);
        world.setBlock(x + 1, y + 5, z + 5, 0);
        world.setBlock(x + 1, y + 5, z + 6, 0);
        world.setBlock(x + 1, y + 5, z + 7, 0);
        world.setBlock(x + 1, y + 5, z + 8, 0);
        world.setBlock(x + 1, y + 5, z + 9, 0);
        world.setBlock(x + 1, y + 5, z + 10, 0);
        world.setBlock(x + 1, y + 5, z + 11, 0);
        world.setBlock(x + 1, y + 5, z + 12, 0);
        world.setBlock(x + 1, y + 5, z + 13, 0);
        world.setBlock(x + 1, y + 5, z + 14, 0);
        world.setBlock(x + 1, y + 5, z + 15, 0);
        world.setBlock(x + 1, y + 5, z + 16, Block.sandStone.blockID, 2, 2);
        world.setBlock(x + 1, y + 6, z + 1, Block.sandStone.blockID, 2, 2);
        world.setBlock(x + 1, y + 6, z + 2, Block.sandStone.blockID, 2, 2);
        world.setBlock(x + 1, y + 6, z + 3, 0);
        world.setBlock(x + 1, y + 6, z + 4, 0);
        world.setBlock(x + 1, y + 6, z + 5, 0);
        world.setBlock(x + 1, y + 6, z + 6, 0);
        world.setBlock(x + 1, y + 6, z + 7, 0);
        world.setBlock(x + 1, y + 6, z + 8, 0);
        world.setBlock(x + 1, y + 6, z + 9, 0);
        world.setBlock(x + 1, y + 6, z + 10, 0);
        world.setBlock(x + 1, y + 6, z + 11, 0);
        world.setBlock(x + 1, y + 6, z + 12, 0);
        world.setBlock(x + 1, y + 6, z + 13, 0);
        world.setBlock(x + 1, y + 6, z + 14, 0);
        world.setBlock(x + 1, y + 6, z + 15, 0);
        world.setBlock(x + 1, y + 6, z + 16, Block.sandStone.blockID, 2, 2);
        world.setBlock(x + 1, y + 7, z + 1, Block.sandStone.blockID, 2, 2);
        world.setBlock(x + 1, y + 7, z + 2, Block.stone.blockID, 0, 2);
        world.setBlock(x + 1, y + 7, z + 3, Block.planks.blockID, 2, 2);
        world.setBlock(x + 1, y + 7, z + 4, Block.planks.blockID, 2, 2);
        world.setBlock(x + 1, y + 7, z + 5, 0);
        world.setBlock(x + 1, y + 7, z + 6, 0);
        world.setBlock(x + 1, y + 7, z + 7, 0);
        world.setBlock(x + 1, y + 7, z + 8, 0);
        world.setBlock(x + 1, y + 7, z + 9, 0);
        world.setBlock(x + 1, y + 7, z + 10, 0);
        world.setBlock(x + 1, y + 7, z + 11, 0);
        world.setBlock(x + 1, y + 7, z + 12, 0);
        world.setBlock(x + 1, y + 7, z + 13, 0);
        world.setBlock(x + 1, y + 7, z + 14, 0);
        world.setBlock(x + 1, y + 7, z + 15, 0);
        world.setBlock(x + 1, y + 7, z + 16, Block.sandStone.blockID, 2, 2);
        world.setBlock(x + 1, y + 8, z + 1, Block.sandStone.blockID, 2, 2);
        world.setBlock(x + 1, y + 8, z + 2, Block.wood.blockID, 1, 2);
        world.setBlock(x + 1, y + 8, z + 3, 0);
        world.setBlock(x + 1, y + 8, z + 4, 0);
        world.setBlock(x + 1, y + 8, z + 5, Block.stairsWoodOak.blockID, 2, 2);
        world.setBlock(x + 1, y + 8, z + 6, 0);
        world.setBlock(x + 1, y + 8, z + 7, 0);
        world.setBlock(x + 1, y + 8, z + 8, 0);
        world.setBlock(x + 1, y + 8, z + 9, 0);
        world.setBlock(x + 1, y + 8, z + 10, 0);
        world.setBlock(x + 1, y + 8, z + 11, 0);
        world.setBlock(x + 1, y + 8, z + 12, 0);
        world.setBlock(x + 1, y + 8, z + 13, 0);
        world.setBlock(x + 1, y + 8, z + 14, 0);
        world.setBlock(x + 1, y + 8, z + 15, 0);
        world.setBlock(x + 1, y + 8, z + 16, Block.sandStone.blockID, 2, 2);
        world.setBlock(x + 1, y + 9, z + 1, Block.sandStone.blockID, 2, 2);
        world.setBlock(x + 1, y + 9, z + 2, Block.wood.blockID, 1, 2);
        world.setBlock(x + 1, y + 9, z + 3, 0);
        world.setBlock(x + 1, y + 9, z + 4, 0);
        world.setBlock(x + 1, y + 9, z + 5, 0);
        world.setBlock(x + 1, y + 9, z + 6, Block.stairsWoodOak.blockID, 2, 2);
        world.setBlock(x + 1, y + 9, z + 7, Block.planks.blockID, 2, 2);
        world.setBlock(x + 1, y + 9, z + 8, Block.planks.blockID, 2, 2);
        world.setBlock(x + 1, y + 9, z + 9, Block.planks.blockID, 2, 2);
        world.setBlock(x + 1, y + 9, z + 10, Block.planks.blockID, 2, 2);
        world.setBlock(x + 1, y + 9, z + 11, Block.planks.blockID, 2, 2);
        world.setBlock(x + 1, y + 9, z + 12, Block.planks.blockID, 2, 2);
        world.setBlock(x + 1, y + 9, z + 13, Block.planks.blockID, 2, 2);
        world.setBlock(x + 1, y + 9, z + 14, Block.planks.blockID, 2, 2);
        world.setBlock(x + 1, y + 9, z + 15, Block.planks.blockID, 2, 2);
        world.setBlock(x + 1, y + 9, z + 16, Block.sandStone.blockID, 2, 2);
        world.setBlock(x + 1, y + 10, z + 1, Block.planks.blockID, 2, 2);
        world.setBlock(x + 1, y + 10, z + 2, Block.wood.blockID, 1, 2);
        world.setBlock(x + 1, y + 10, z + 3, 0);
        world.setBlock(x + 1, y + 10, z + 4, 0);
        world.setBlock(x + 1, y + 10, z + 5, 0);
        world.setBlock(x + 1, y + 10, z + 6, 0);
        world.setBlock(x + 1, y + 10, z + 7, 0);
        world.setBlock(x + 1, y + 10, z + 8, 0);
        world.setBlock(x + 1, y + 10, z + 9, 0);
        world.setBlock(x + 1, y + 10, z + 10, 0);
        world.setBlock(x + 1, y + 10, z + 11, 0);
        world.setBlock(x + 1, y + 10, z + 12, 0);
        world.setBlock(x + 1, y + 10, z + 13, 0);
        world.setBlock(x + 1, y + 10, z + 14, 0);
        world.setBlock(x + 1, y + 10, z + 15, Block.wood.blockID, 1, 2);
        world.setBlock(x + 1, y + 10, z + 16, Block.planks.blockID, 2, 2);
        world.setBlock(x + 1, y + 11, z + 1, Block.planks.blockID, 2, 2);
        world.setBlock(x + 1, y + 11, z + 2, Block.wood.blockID, 1, 2);
        world.setBlock(x + 1, y + 11, z + 3, 0);
        world.setBlock(x + 1, y + 11, z + 4, 0);
        world.setBlock(x + 1, y + 11, z + 5, 0);
        world.setBlock(x + 1, y + 11, z + 6, 0);
        world.setBlock(x + 1, y + 11, z + 7, 0);
        world.setBlock(x + 1, y + 11, z + 8, 0);
        world.setBlock(x + 1, y + 11, z + 9, 0);
        world.setBlock(x + 1, y + 11, z + 10, 0);
        world.setBlock(x + 1, y + 11, z + 11, 0);
        world.setBlock(x + 1, y + 11, z + 12, 0);
        world.setBlock(x + 1, y + 11, z + 13, 0);
        world.setBlock(x + 1, y + 11, z + 14, 0);
        world.setBlock(x + 1, y + 11, z + 15, Block.wood.blockID, 1, 2);
        world.setBlock(x + 1, y + 11, z + 16, Block.planks.blockID, 2, 2);
        world.setBlock(x + 1, y + 12, z + 1, Block.planks.blockID, 2, 2);
        world.setBlock(x + 1, y + 12, z + 2, Block.wood.blockID, 1, 2);
        world.setBlock(x + 1, y + 12, z + 4, 0);
        world.setBlock(x + 1, y + 12, z + 5, 0);
        world.setBlock(x + 1, y + 12, z + 7, 0);
        world.setBlock(x + 1, y + 12, z + 8, 0);
        world.setBlock(x + 1, y + 12, z + 9, 0);
        world.setBlock(x + 1, y + 12, z + 11, 0);
        world.setBlock(x + 1, y + 12, z + 12, 0);
        world.setBlock(x + 1, y + 12, z + 13, 0);
        world.setBlock(x + 1, y + 12, z + 15, Block.wood.blockID, 1, 2);
        world.setBlock(x + 1, y + 12, z + 16, Block.planks.blockID, 2, 2);
        world.setBlock(x + 1, y + 13, z + 1, Block.planks.blockID, 2, 2);
        world.setBlock(x + 1, y + 13, z + 2, Block.wood.blockID, 1, 2);
        world.setBlock(x + 1, y + 13, z + 3, Block.woodDoubleSlab.blockID, 0, 2);
        world.setBlock(x + 1, y + 13, z + 4, Block.stairsWoodOak.blockID, 7, 2);
        world.setBlock(x + 1, y + 13, z + 5, 0);
        world.setBlock(x + 1, y + 13, z + 6, 0);
        world.setBlock(x + 1, y + 13, z + 7, 0);
        world.setBlock(x + 1, y + 13, z + 8, 0);
        world.setBlock(x + 1, y + 13, z + 9, 0);
        world.setBlock(x + 1, y + 13, z + 10, 0);
        world.setBlock(x + 1, y + 13, z + 11, 0);
        world.setBlock(x + 1, y + 13, z + 12, 0);
        world.setBlock(x + 1, y + 13, z + 13, 0);
        world.setBlock(x + 1, y + 13, z + 14, 0);
        world.setBlock(x + 1, y + 13, z + 15, Block.wood.blockID, 1, 2);
        world.setBlock(x + 1, y + 13, z + 16, Block.planks.blockID, 2, 2);
        world.setBlock(x + 1, y + 14, z + 0, 0);
        world.setBlock(x + 1, y + 14, z + 1, Block.planks.blockID, 2, 2);
        world.setBlock(x + 1, y + 14, z + 2, Block.wood.blockID, 1, 2);
        world.setBlock(x + 1, y + 14, z + 3, Block.fence.blockID, 0, 2);
        world.setBlock(x + 1, y + 14, z + 4, Block.fence.blockID, 0, 2);
        world.setBlock(x + 1, y + 14, z + 5, 0);
        world.setBlock(x + 1, y + 14, z + 6, 0);
        world.setBlock(x + 1, y + 14, z + 7, 0);
        world.setBlock(x + 1, y + 14, z + 8, 0);
        world.setBlock(x + 1, y + 14, z + 9, 0);
        world.setBlock(x + 1, y + 14, z + 10, 0);
        world.setBlock(x + 1, y + 14, z + 11, 0);
        world.setBlock(x + 1, y + 14, z + 12, 0);
        world.setBlock(x + 1, y + 14, z + 13, 0);
        world.setBlock(x + 1, y + 14, z + 14, 0);
        world.setBlock(x + 1, y + 14, z + 15, Block.wood.blockID, 1, 2);
        world.setBlock(x + 1, y + 14, z + 16, Block.sandStone.blockID, 2, 2);
        world.setBlock(x + 1, y + 14, z + 17, 0);
        world.setBlock(x + 1, y + 15, z + 1, Block.planks.blockID, 2, 2);
        world.setBlock(x + 1, y + 15, z + 2, Block.wood.blockID, 1, 2);
        world.setBlock(x + 1, y + 15, z + 3, Block.fence.blockID, 0, 2);
        world.setBlock(x + 1, y + 15, z + 5, 0);
        world.setBlock(x + 1, y + 15, z + 6, 0);
        world.setBlock(x + 1, y + 15, z + 7, 0);
        world.setBlock(x + 1, y + 15, z + 8, 0);
        world.setBlock(x + 1, y + 15, z + 9, 0);
        world.setBlock(x + 1, y + 15, z + 10, 0);
        world.setBlock(x + 1, y + 15, z + 11, 0);
        world.setBlock(x + 1, y + 15, z + 12, 0);
        world.setBlock(x + 1, y + 15, z + 13, 0);
        world.setBlock(x + 1, y + 15, z + 14, 0);
        world.setBlock(x + 1, y + 15, z + 15, Block.wood.blockID, 1, 2);
        world.setBlock(x + 1, y + 15, z + 16, Block.sandStone.blockID, 2, 2);
        world.setBlock(x + 1, y + 15, z + 17, 0);
        world.setBlock(x + 1, y + 16, z + 0, 0);
        world.setBlock(x + 1, y + 16, z + 1, Block.planks.blockID, 2, 2);
        world.setBlock(x + 1, y + 16, z + 2, Block.wood.blockID, 1, 2);
        world.setBlock(x + 1, y + 16, z + 3, Block.planks.blockID, 2, 2);
        world.setBlock(x + 1, y + 16, z + 4, Block.planks.blockID, 2, 2);
        world.setBlock(x + 1, y + 16, z + 5, Block.planks.blockID, 2, 2);
        world.setBlock(x + 1, y + 16, z + 6, Block.planks.blockID, 2, 2);
        world.setBlock(x + 1, y + 16, z + 7, Block.planks.blockID, 2, 2);
        world.setBlock(x + 1, y + 16, z + 8, Block.planks.blockID, 2, 2);
        world.setBlock(x + 1, y + 16, z + 9, Block.planks.blockID, 2, 2);
        world.setBlock(x + 1, y + 16, z + 10, Block.planks.blockID, 2, 2);
        world.setBlock(x + 1, y + 16, z + 11, Block.planks.blockID, 2, 2);
        world.setBlock(x + 1, y + 16, z + 12, Block.planks.blockID, 2, 2);
        world.setBlock(x + 1, y + 16, z + 13, Block.planks.blockID, 2, 2);
        world.setBlock(x + 1, y + 16, z + 14, Block.planks.blockID, 2, 2);
        world.setBlock(x + 1, y + 16, z + 15, Block.wood.blockID, 1, 2);
        world.setBlock(x + 1, y + 16, z + 16, Block.sandStone.blockID, 2, 2);
        world.setBlock(x + 1, y + 16, z + 17, 0);
        world.setBlock(x + 1, y + 17, z + 0, 0);
        world.setBlock(x + 1, y + 17, z + 1, Block.sandStone.blockID, 2, 2);
        world.setBlock(x + 1, y + 17, z + 2, Block.wood.blockID, 1, 2);
        world.setBlock(x + 1, y + 17, z + 3, Block.fence.blockID, 0, 2);
        world.setBlock(x + 1, y + 17, z + 4, Block.fence.blockID, 0, 2);
        world.setBlock(x + 1, y + 17, z + 5, Block.fence.blockID, 0, 2);
        world.setBlock(x + 1, y + 17, z + 6, Block.fence.blockID, 0, 2);
        world.setBlock(x + 1, y + 17, z + 7, 0);
        world.setBlock(x + 1, y + 17, z + 8, 0);
        world.setBlock(x + 1, y + 17, z + 9, 0);
        world.setBlock(x + 1, y + 17, z + 10, 0);
        world.setBlock(x + 1, y + 17, z + 11, 0);
        world.setBlock(x + 1, y + 17, z + 12, Block.workbench.blockID, 0, 2);
        world.setBlock(x + 1, y + 17, z + 13, Block.chest.blockID, 5, 2);
        world.setBlock(x + 1, y + 17, z + 14, Block.chest.blockID, 5, 2);
        world.setBlock(x + 1, y + 17, z + 15, Block.wood.blockID, 1, 2);
        world.setBlock(x + 1, y + 17, z + 16, Block.sandStone.blockID, 2, 2);
        world.setBlock(x + 1, y + 17, z + 17, 0);
        world.setBlock(x + 1, y + 18, z + 0, 0);
        world.setBlock(x + 1, y + 18, z + 1, Block.sandStone.blockID, 2, 2);
        world.setBlock(x + 1, y + 18, z + 2, Block.wood.blockID, 1, 2);
        world.setBlock(x + 1, y + 18, z + 3, 0);
        world.setBlock(x + 1, y + 18, z + 4, 0);
        world.setBlock(x + 1, y + 18, z + 5, 0);
        world.setBlock(x + 1, y + 18, z + 6, 0);
        world.setBlock(x + 1, y + 18, z + 7, 0);
        world.setBlock(x + 1, y + 18, z + 8, 0);
        world.setBlock(x + 1, y + 18, z + 9, 0);
        world.setBlock(x + 1, y + 18, z + 10, 0);
        world.setBlock(x + 1, y + 18, z + 11, 0);
        world.setBlock(x + 1, y + 18, z + 12, 0);
        world.setBlock(x + 1, y + 18, z + 13, 0);
        world.setBlock(x + 1, y + 18, z + 14, 0);
        world.setBlock(x + 1, y + 18, z + 15, Block.wood.blockID, 1, 2);
        world.setBlock(x + 1, y + 18, z + 16, Block.sandStone.blockID, 2, 2);
        world.setBlock(x + 1, y + 18, z + 17, 0);
        world.setBlock(x + 1, y + 19, z + 0, Block.stairsSandStone.blockID, 2, 2);
        world.setBlock(x + 1, y + 19, z + 1, Block.sandStone.blockID, 2, 2);
        world.setBlock(x + 1, y + 19, z + 2, Block.wood.blockID, 1, 2);
        world.setBlock(x + 1, y + 19, z + 4, 0);
        world.setBlock(x + 1, y + 19, z + 5, 0);
        world.setBlock(x + 1, y + 19, z + 6, 0);
        world.setBlock(x + 1, y + 19, z + 7, 0);
        world.setBlock(x + 1, y + 19, z + 8, 0);
        world.setBlock(x + 1, y + 19, z + 9, 0);
        world.setBlock(x + 1, y + 19, z + 10, 0);
        world.setBlock(x + 1, y + 19, z + 11, 0);
        world.setBlock(x + 1, y + 19, z + 12, 0);
        world.setBlock(x + 1, y + 19, z + 13, 0);
        world.setBlock(x + 1, y + 19, z + 15, Block.wood.blockID, 1, 2);
        world.setBlock(x + 1, y + 19, z + 16, Block.sandStone.blockID, 2, 2);
        world.setBlock(x + 1, y + 19, z + 17, Block.stairsSandStone.blockID, 3, 2);
        world.setBlock(x + 1, y + 20, z + 0, 0);
        world.setBlock(x + 1, y + 20, z + 1, Block.stairsSandStone.blockID, 2, 2);
        world.setBlock(x + 1, y + 20, z + 2, Block.wood.blockID, 1, 2);
        world.setBlock(x + 1, y + 20, z + 3, Block.planks.blockID, 2, 2);
        world.setBlock(x + 1, y + 20, z + 4, Block.planks.blockID, 2, 2);
        world.setBlock(x + 1, y + 20, z + 5, Block.planks.blockID, 2, 2);
        world.setBlock(x + 1, y + 20, z + 6, Block.planks.blockID, 2, 2);
        world.setBlock(x + 1, y + 20, z + 7, Block.planks.blockID, 2, 2);
        world.setBlock(x + 1, y + 20, z + 8, Block.planks.blockID, 2, 2);
        world.setBlock(x + 1, y + 20, z + 9, Block.planks.blockID, 2, 2);
        world.setBlock(x + 1, y + 20, z + 10, Block.planks.blockID, 2, 2);
        world.setBlock(x + 1, y + 20, z + 11, Block.planks.blockID, 2, 2);
        world.setBlock(x + 1, y + 20, z + 12, Block.planks.blockID, 2, 2);
        world.setBlock(x + 1, y + 20, z + 13, Block.planks.blockID, 2, 2);
        world.setBlock(x + 1, y + 20, z + 14, Block.planks.blockID, 2, 2);
        world.setBlock(x + 1, y + 20, z + 15, Block.wood.blockID, 1, 2);
        world.setBlock(x + 1, y + 20, z + 16, Block.stairsSandStone.blockID, 3, 2);
        world.setBlock(x + 1, y + 20, z + 17, 0);
        world.setBlock(x + 1, y + 21, z + 0, 0);
        world.setBlock(x + 1, y + 21, z + 1, 0);
        world.setBlock(x + 1, y + 21, z + 2, Block.stairsSandStone.blockID, 2, 2);
        world.setBlock(x + 1, y + 21, z + 3, Block.stairsSandStone.blockID, 7, 2);
        world.setBlock(x + 1, y + 21, z + 4, 0);
        world.setBlock(x + 1, y + 21, z + 5, Block.web.blockID, 0, 2);
        world.setBlock(x + 1, y + 21, z + 6, 0);
        world.setBlock(x + 1, y + 21, z + 7, 0);
        world.setBlock(x + 1, y + 21, z + 8, 0);
        world.setBlock(x + 1, y + 21, z + 9, 0);
        world.setBlock(x + 1, y + 21, z + 10, Block.web.blockID, 0, 2);
        world.setBlock(x + 1, y + 21, z + 11, 0);
        world.setBlock(x + 1, y + 21, z + 12, 0);
        world.setBlock(x + 1, y + 21, z + 13, 0);
        world.setBlock(x + 1, y + 21, z + 14, Block.stairsSandStone.blockID, 6, 2);
        world.setBlock(x + 1, y + 21, z + 15, Block.stairsSandStone.blockID, 3, 2);
        world.setBlock(x + 1, y + 21, z + 16, 0);
        world.setBlock(x + 1, y + 21, z + 17, 0);
        world.setBlock(x + 1, y + 22, z + 0, 0);
        world.setBlock(x + 1, y + 22, z + 1, 0);
        world.setBlock(x + 1, y + 22, z + 2, 0);
        world.setBlock(x + 1, y + 22, z + 3, Block.stairsSandStone.blockID, 2, 2);
        world.setBlock(x + 1, y + 22, z + 4, Block.stairsSandStone.blockID, 7, 2);
        world.setBlock(x + 1, y + 22, z + 5, 0);
        world.setBlock(x + 1, y + 22, z + 6, 0);
        world.setBlock(x + 1, y + 22, z + 7, 0);
        world.setBlock(x + 1, y + 22, z + 8, 0);
        world.setBlock(x + 1, y + 22, z + 9, 0);
        world.setBlock(x + 1, y + 22, z + 10, 0);
        world.setBlock(x + 1, y + 22, z + 11, 0);
        world.setBlock(x + 1, y + 22, z + 12, 0);
        world.setBlock(x + 1, y + 22, z + 13, Block.stairsSandStone.blockID, 6, 2);
        world.setBlock(x + 1, y + 22, z + 14, Block.stairsSandStone.blockID, 3, 2);
        world.setBlock(x + 1, y + 22, z + 15, 0);
        world.setBlock(x + 1, y + 22, z + 16, 0);
        world.setBlock(x + 1, y + 22, z + 17, 0);
        world.setBlock(x + 1, y + 23, z + 0, 0);
        world.setBlock(x + 1, y + 23, z + 1, 0);
        world.setBlock(x + 1, y + 23, z + 2, 0);
        world.setBlock(x + 1, y + 23, z + 3, 0);
        world.setBlock(x + 1, y + 23, z + 4, Block.stairsSandStone.blockID, 2, 2);
        world.setBlock(x + 1, y + 23, z + 5, Block.stairsSandStone.blockID, 7, 2);
        world.setBlock(x + 1, y + 23, z + 6, 0);
        world.setBlock(x + 1, y + 23, z + 7, Block.web.blockID, 0, 2);
        world.setBlock(x + 1, y + 23, z + 8, 0);
        world.setBlock(x + 1, y + 23, z + 9, 0);
        world.setBlock(x + 1, y + 23, z + 10, 0);
        world.setBlock(x + 1, y + 23, z + 11, 0);
        world.setBlock(x + 1, y + 23, z + 12, Block.stairsSandStone.blockID, 6, 2);
        world.setBlock(x + 1, y + 23, z + 13, Block.stairsSandStone.blockID, 3, 2);
        world.setBlock(x + 1, y + 23, z + 14, 0);
        world.setBlock(x + 1, y + 23, z + 15, 0);
        world.setBlock(x + 1, y + 23, z + 16, 0);
        world.setBlock(x + 1, y + 23, z + 17, 0);
        world.setBlock(x + 1, y + 24, z + 0, 0);
        world.setBlock(x + 1, y + 24, z + 1, 0);
        world.setBlock(x + 1, y + 24, z + 2, 0);
        world.setBlock(x + 1, y + 24, z + 3, 0);
        world.setBlock(x + 1, y + 24, z + 4, 0);
        world.setBlock(x + 1, y + 24, z + 5, Block.stairsSandStone.blockID, 2, 2);
        world.setBlock(x + 1, y + 24, z + 6, Block.stairsSandStone.blockID, 7, 2);
        world.setBlock(x + 1, y + 24, z + 7, 0);
        world.setBlock(x + 1, y + 24, z + 8, 0);
        world.setBlock(x + 1, y + 24, z + 9, 0);
        world.setBlock(x + 1, y + 24, z + 10, 0);
        world.setBlock(x + 1, y + 24, z + 11, Block.stairsSandStone.blockID, 6, 2);
        world.setBlock(x + 1, y + 24, z + 12, Block.stairsSandStone.blockID, 3, 2);
        world.setBlock(x + 1, y + 24, z + 13, 0);
        world.setBlock(x + 1, y + 24, z + 14, 0);
        world.setBlock(x + 1, y + 24, z + 15, 0);
        world.setBlock(x + 1, y + 24, z + 16, 0);
        world.setBlock(x + 1, y + 24, z + 17, 0);
        world.setBlock(x + 1, y + 25, z + 0, 0);
        world.setBlock(x + 1, y + 25, z + 1, 0);
        world.setBlock(x + 1, y + 25, z + 2, 0);
        world.setBlock(x + 1, y + 25, z + 3, 0);
        world.setBlock(x + 1, y + 25, z + 4, 0);
        world.setBlock(x + 1, y + 25, z + 5, 0);
        world.setBlock(x + 1, y + 25, z + 6, Block.stoneSingleSlab.blockID, 1, 2);
        world.setBlock(x + 1, y + 25, z + 7, Block.stoneSingleSlab.blockID, 1, 2);
        world.setBlock(x + 1, y + 25, z + 8, Block.stoneSingleSlab.blockID, 1, 2);
        world.setBlock(x + 1, y + 25, z + 9, Block.stoneSingleSlab.blockID, 1, 2);
        world.setBlock(x + 1, y + 25, z + 10, Block.stoneSingleSlab.blockID, 1, 2);
        world.setBlock(x + 1, y + 25, z + 11, Block.stoneSingleSlab.blockID, 1, 2);
        world.setBlock(x + 1, y + 25, z + 12, 0);
        world.setBlock(x + 1, y + 25, z + 13, 0);
        world.setBlock(x + 1, y + 25, z + 14, 0);
        world.setBlock(x + 1, y + 25, z + 15, 0);
        world.setBlock(x + 1, y + 25, z + 16, 0);
        world.setBlock(x + 1, y + 25, z + 17, 0);
        world.setBlock(x + 2, y + 0, z + 1, Block.sandStone.blockID, 2, 2);
        world.setBlock(x + 2, y + 0, z + 2, Block.stone.blockID, 0, 2);
        world.setBlock(x + 2, y + 0, z + 3, Block.stainedClay.blockID, 9, 2);
        world.setBlock(x + 2, y + 0, z + 4, Block.stainedClay.blockID, 9, 2);
        world.setBlock(x + 2, y + 0, z + 5, Block.stainedClay.blockID, 9, 2);
        world.setBlock(x + 2, y + 0, z + 6, Block.stainedClay.blockID, 9, 2);
        world.setBlock(x + 2, y + 0, z + 7, Block.stainedClay.blockID, 9, 2);
        world.setBlock(x + 2, y + 0, z + 8, Block.stainedClay.blockID, 9, 2);
        world.setBlock(x + 2, y + 0, z + 9, Block.stainedClay.blockID, 9, 2);
        world.setBlock(x + 2, y + 0, z + 10, Block.stainedClay.blockID, 9, 2);
        world.setBlock(x + 2, y + 0, z + 11, Block.stainedClay.blockID, 9, 2);
        world.setBlock(x + 2, y + 0, z + 12, Block.stainedClay.blockID, 9, 2);
        world.setBlock(x + 2, y + 0, z + 13, Block.stainedClay.blockID, 9, 2);
        world.setBlock(x + 2, y + 0, z + 14, Block.stainedClay.blockID, 9, 2);
        world.setBlock(x + 2, y + 0, z + 15, Block.stainedClay.blockID, 9, 2);
        world.setBlock(x + 2, y + 0, z + 16, Block.sandStone.blockID, 2, 2);
        world.setBlock(x + 2, y + 1, z + 1, Block.sandStone.blockID, 2, 2);
        world.setBlock(x + 2, y + 1, z + 2, Block.sandStone.blockID, 2, 2);
        world.setBlock(x + 2, y + 1, z + 3, 0);
        world.setBlock(x + 2, y + 1, z + 4, 0);
        world.setBlock(x + 2, y + 1, z + 5, 0);
        world.setBlock(x + 2, y + 1, z + 6, 0);
        world.setBlock(x + 2, y + 1, z + 7, 0);
        world.setBlock(x + 2, y + 1, z + 8, 0);
        world.setBlock(x + 2, y + 1, z + 9, 0);
        world.setBlock(x + 2, y + 1, z + 10, 0);
        world.setBlock(x + 2, y + 1, z + 11, 0);
        world.setBlock(x + 2, y + 1, z + 12, 0);
        world.setBlock(x + 2, y + 1, z + 13, 0);
        world.setBlock(x + 2, y + 1, z + 14, 0);
        world.setBlock(x + 2, y + 1, z + 15, 0);
        world.setBlock(x + 2, y + 1, z + 16, Block.sandStone.blockID, 2, 2);
        world.setBlock(x + 2, y + 2, z + 1, Block.sandStone.blockID, 2, 2);
        world.setBlock(x + 2, y + 2, z + 2, Block.sandStone.blockID, 2, 2);
        world.setBlock(x + 2, y + 2, z + 3, 0);
        world.setBlock(x + 2, y + 2, z + 4, 0);
        world.setBlock(x + 2, y + 2, z + 5, 0);
        world.setBlock(x + 2, y + 2, z + 6, 0);
        world.setBlock(x + 2, y + 2, z + 7, 0);
        world.setBlock(x + 2, y + 2, z + 8, 0);
        world.setBlock(x + 2, y + 2, z + 9, 0);
        world.setBlock(x + 2, y + 2, z + 10, 0);
        world.setBlock(x + 2, y + 2, z + 11, 0);
        world.setBlock(x + 2, y + 2, z + 12, 0);
        world.setBlock(x + 2, y + 2, z + 13, 0);
        world.setBlock(x + 2, y + 2, z + 14, 0);
        world.setBlock(x + 2, y + 2, z + 15, 0);
        world.setBlock(x + 2, y + 2, z + 16, Block.sandStone.blockID, 2, 2);
        world.setBlock(x + 2, y + 3, z + 1, Block.sandStone.blockID, 2, 2);
        world.setBlock(x + 2, y + 3, z + 2, Block.sandStone.blockID, 2, 2);
        world.setBlock(x + 2, y + 3, z + 3, 0);
        world.setBlock(x + 2, y + 3, z + 4, 0);
        world.setBlock(x + 2, y + 3, z + 5, 0);
        world.setBlock(x + 2, y + 3, z + 6, 0);
        world.setBlock(x + 2, y + 3, z + 7, 0);
        world.setBlock(x + 2, y + 3, z + 8, 0);
        world.setBlock(x + 2, y + 3, z + 9, 0);
        world.setBlock(x + 2, y + 3, z + 10, 0);
        world.setBlock(x + 2, y + 3, z + 11, 0);
        world.setBlock(x + 2, y + 3, z + 12, 0);
        world.setBlock(x + 2, y + 3, z + 13, 0);
        world.setBlock(x + 2, y + 3, z + 14, 0);
        world.setBlock(x + 2, y + 3, z + 15, 0);
        world.setBlock(x + 2, y + 3, z + 16, Block.sandStone.blockID, 2, 2);
        world.setBlock(x + 2, y + 4, z + 1, Block.sandStone.blockID, 2, 2);
        world.setBlock(x + 2, y + 4, z + 2, Block.sandStone.blockID, 2, 2);
        world.setBlock(x + 2, y + 4, z + 3, Block.glass.blockID, 0, 2);
        world.setBlock(x + 2, y + 4, z + 4, Block.glass.blockID, 0, 2);
        world.setBlock(x + 2, y + 4, z + 5, Block.glass.blockID, 0, 2);
        world.setBlock(x + 2, y + 4, z + 6, Block.glass.blockID, 0, 2);
        world.setBlock(x + 2, y + 4, z + 7, Block.glass.blockID, 0, 2);
        world.setBlock(x + 2, y + 4, z + 8, Block.glass.blockID, 0, 2);
        world.setBlock(x + 2, y + 4, z + 9, Block.glass.blockID, 0, 2);
        world.setBlock(x + 2, y + 4, z + 10, Block.glass.blockID, 0, 2);
        world.setBlock(x + 2, y + 4, z + 11, Block.glass.blockID, 0, 2);
        world.setBlock(x + 2, y + 4, z + 12, Block.glass.blockID, 0, 2);
        world.setBlock(x + 2, y + 4, z + 13, Block.glass.blockID, 0, 2);
        world.setBlock(x + 2, y + 4, z + 14, Block.glass.blockID, 0, 2);
        world.setBlock(x + 2, y + 4, z + 15, Block.glass.blockID, 0, 2);
        world.setBlock(x + 2, y + 4, z + 16, Block.sandStone.blockID, 2, 2);
        world.setBlock(x + 2, y + 5, z + 1, Block.sandStone.blockID, 2, 2);
        world.setBlock(x + 2, y + 5, z + 2, Block.sandStone.blockID, 2, 2);
        world.setBlock(x + 2, y + 5, z + 3, 0);
        world.setBlock(x + 2, y + 5, z + 4, 0);
        world.setBlock(x + 2, y + 5, z + 5, 0);
        world.setBlock(x + 2, y + 5, z + 6, 0);
        world.setBlock(x + 2, y + 5, z + 7, 0);
        world.setBlock(x + 2, y + 5, z + 8, 0);
        world.setBlock(x + 2, y + 5, z + 9, 0);
        world.setBlock(x + 2, y + 5, z + 10, 0);
        world.setBlock(x + 2, y + 5, z + 11, 0);
        world.setBlock(x + 2, y + 5, z + 12, 0);
        world.setBlock(x + 2, y + 5, z + 13, 0);
        world.setBlock(x + 2, y + 5, z + 14, 0);
        world.setBlock(x + 2, y + 5, z + 15, 0);
        world.setBlock(x + 2, y + 5, z + 16, Block.sandStone.blockID, 2, 2);
        world.setBlock(x + 2, y + 6, z + 1, Block.sandStone.blockID, 2, 2);
        world.setBlock(x + 2, y + 6, z + 2, Block.sandStone.blockID, 2, 2);
        world.setBlock(x + 2, y + 6, z + 3, 0);
        world.setBlock(x + 2, y + 6, z + 4, 0);
        world.setBlock(x + 2, y + 6, z + 5, 0);
        world.setBlock(x + 2, y + 6, z + 6, 0);
        world.setBlock(x + 2, y + 6, z + 7, 0);
        world.setBlock(x + 2, y + 6, z + 8, 0);
        world.setBlock(x + 2, y + 6, z + 9, 0);
        world.setBlock(x + 2, y + 6, z + 10, 0);
        world.setBlock(x + 2, y + 6, z + 11, 0);
        world.setBlock(x + 2, y + 6, z + 12, 0);
        world.setBlock(x + 2, y + 6, z + 13, 0);
        world.setBlock(x + 2, y + 6, z + 14, 0);
        world.setBlock(x + 2, y + 6, z + 15, 0);
        world.setBlock(x + 2, y + 6, z + 16, Block.sandStone.blockID, 2, 2);
        world.setBlock(x + 2, y + 7, z + 1, Block.sandStone.blockID, 2, 2);
        world.setBlock(x + 2, y + 7, z + 2, Block.planks.blockID, 2, 2);
        world.setBlock(x + 2, y + 7, z + 3, Block.planks.blockID, 2, 2);
        world.setBlock(x + 2, y + 7, z + 4, Block.planks.blockID, 2, 2);
        world.setBlock(x + 2, y + 7, z + 5, 0);
        world.setBlock(x + 2, y + 7, z + 6, 0);
        world.setBlock(x + 2, y + 7, z + 7, 0);
        world.setBlock(x + 2, y + 7, z + 8, 0);
        world.setBlock(x + 2, y + 7, z + 9, 0);
        world.setBlock(x + 2, y + 7, z + 10, 0);
        world.setBlock(x + 2, y + 7, z + 11, 0);
        world.setBlock(x + 2, y + 7, z + 12, 0);
        world.setBlock(x + 2, y + 7, z + 13, 0);
        world.setBlock(x + 2, y + 7, z + 14, 0);
        world.setBlock(x + 2, y + 7, z + 15, 0);
        world.setBlock(x + 2, y + 7, z + 16, Block.sandStone.blockID, 2, 2);
        world.setBlock(x + 2, y + 8, z + 1, Block.sandStone.blockID, 2, 2);
        world.setBlock(x + 2, y + 8, z + 2, Block.planks.blockID, 2, 2);
        world.setBlock(x + 2, y + 8, z + 3, 0);
        world.setBlock(x + 2, y + 8, z + 4, 0);
        world.setBlock(x + 2, y + 8, z + 5, Block.stairsWoodOak.blockID, 2, 2);
        world.setBlock(x + 2, y + 8, z + 6, 0);
        world.setBlock(x + 2, y + 8, z + 7, 0);
        world.setBlock(x + 2, y + 8, z + 8, 0);
        world.setBlock(x + 2, y + 8, z + 9, 0);
        world.setBlock(x + 2, y + 8, z + 10, 0);
        world.setBlock(x + 2, y + 8, z + 11, 0);
        world.setBlock(x + 2, y + 8, z + 12, 0);
        world.setBlock(x + 2, y + 8, z + 13, 0);
        world.setBlock(x + 2, y + 8, z + 14, 0);
        world.setBlock(x + 2, y + 8, z + 15, 0);
        world.setBlock(x + 2, y + 8, z + 16, Block.sandStone.blockID, 2, 2);
        world.setBlock(x + 2, y + 9, z + 1, Block.sandStone.blockID, 2, 2);
        world.setBlock(x + 2, y + 9, z + 2, 0);
        world.setBlock(x + 2, y + 9, z + 3, 0);
        world.setBlock(x + 2, y + 9, z + 4, 0);
        world.setBlock(x + 2, y + 9, z + 5, 0);
        world.setBlock(x + 2, y + 9, z + 6, Block.stairsWoodOak.blockID, 2, 2);
        world.setBlock(x + 2, y + 9, z + 7, Block.planks.blockID, 2, 2);
        world.setBlock(x + 2, y + 9, z + 8, Block.planks.blockID, 2, 2);
        world.setBlock(x + 2, y + 9, z + 9, Block.planks.blockID, 2, 2);
        world.setBlock(x + 2, y + 9, z + 10, Block.planks.blockID, 2, 2);
        world.setBlock(x + 2, y + 9, z + 11, Block.planks.blockID, 2, 2);
        world.setBlock(x + 2, y + 9, z + 12, Block.planks.blockID, 2, 2);
        world.setBlock(x + 2, y + 9, z + 13, Block.planks.blockID, 2, 2);
        world.setBlock(x + 2, y + 9, z + 14, Block.planks.blockID, 2, 2);
        world.setBlock(x + 2, y + 9, z + 15, Block.planks.blockID, 2, 2);
        world.setBlock(x + 2, y + 9, z + 16, Block.sandStone.blockID, 2, 2);
        world.setBlock(x + 2, y + 10, z + 1, Block.planks.blockID, 2, 2);
        world.setBlock(x + 2, y + 10, z + 2, 0);
        world.setBlock(x + 2, y + 10, z + 3, 0);
        world.setBlock(x + 2, y + 10, z + 4, 0);
        world.setBlock(x + 2, y + 10, z + 5, 0);
        world.setBlock(x + 2, y + 10, z + 6, 0);
        world.setBlock(x + 2, y + 10, z + 7, 0);
        world.setBlock(x + 2, y + 10, z + 8, 0);
        world.setBlock(x + 2, y + 10, z + 9, 0);
        world.setBlock(x + 2, y + 10, z + 10, 0);
        world.setBlock(x + 2, y + 10, z + 11, 0);
        world.setBlock(x + 2, y + 10, z + 12, 0);
        world.setBlock(x + 2, y + 10, z + 13, 0);
        world.setBlock(x + 2, y + 10, z + 14, 0);
        world.setBlock(x + 2, y + 10, z + 15, 0);
        world.setBlock(x + 2, y + 10, z + 16, Block.planks.blockID, 2, 2);
        world.setBlock(x + 2, y + 11, z + 1, Block.planks.blockID, 2, 2);
        world.setBlock(x + 2, y + 11, z + 2, 0);
        world.setBlock(x + 2, y + 11, z + 3, 0);
        world.setBlock(x + 2, y + 11, z + 4, 0);
        world.setBlock(x + 2, y + 11, z + 5, 0);
        world.setBlock(x + 2, y + 11, z + 6, 0);
        world.setBlock(x + 2, y + 11, z + 7, 0);
        world.setBlock(x + 2, y + 11, z + 8, 0);
        world.setBlock(x + 2, y + 11, z + 9, 0);
        world.setBlock(x + 2, y + 11, z + 10, 0);
        world.setBlock(x + 2, y + 11, z + 11, 0);
        world.setBlock(x + 2, y + 11, z + 12, 0);
        world.setBlock(x + 2, y + 11, z + 13, 0);
        world.setBlock(x + 2, y + 11, z + 14, 0);
        world.setBlock(x + 2, y + 11, z + 15, 0);
        world.setBlock(x + 2, y + 11, z + 16, Block.planks.blockID, 2, 2);
        world.setBlock(x + 2, y + 12, z + 1, Block.planks.blockID, 2, 2);
        world.setBlock(x + 2, y + 12, z + 3, 0);
        world.setBlock(x + 2, y + 12, z + 4, 0);
        world.setBlock(x + 2, y + 12, z + 5, 0);
        world.setBlock(x + 2, y + 12, z + 6, 0);
        world.setBlock(x + 2, y + 12, z + 7, 0);
        world.setBlock(x + 2, y + 12, z + 8, 0);
        world.setBlock(x + 2, y + 12, z + 9, 0);
        world.setBlock(x + 2, y + 12, z + 10, 0);
        world.setBlock(x + 2, y + 12, z + 11, 0);
        world.setBlock(x + 2, y + 12, z + 12, 0);
        world.setBlock(x + 2, y + 12, z + 13, 0);
        world.setBlock(x + 2, y + 12, z + 14, 0);
        world.setBlock(x + 2, y + 12, z + 16, Block.planks.blockID, 2, 2);
        world.setBlock(x + 2, y + 13, z + 1, Block.planks.blockID, 2, 2);
        world.setBlock(x + 2, y + 13, z + 2, Block.woodDoubleSlab.blockID, 0, 2);
        world.setBlock(x + 2, y + 13, z + 3, Block.woodDoubleSlab.blockID, 0, 2);
        world.setBlock(x + 2, y + 13, z + 4, Block.stairsWoodOak.blockID, 7, 2);
        world.setBlock(x + 2, y + 13, z + 5, 0);
        world.setBlock(x + 2, y + 13, z + 6, 0);
        world.setBlock(x + 2, y + 13, z + 7, 0);
        world.setBlock(x + 2, y + 13, z + 8, 0);
        world.setBlock(x + 2, y + 13, z + 9, 0);
        world.setBlock(x + 2, y + 13, z + 10, 0);
        world.setBlock(x + 2, y + 13, z + 11, 0);
        world.setBlock(x + 2, y + 13, z + 12, 0);
        world.setBlock(x + 2, y + 13, z + 13, 0);
        world.setBlock(x + 2, y + 13, z + 14, 0);
        world.setBlock(x + 2, y + 13, z + 15, 0);
        world.setBlock(x + 2, y + 13, z + 16, Block.planks.blockID, 2, 2);
        world.setBlock(x + 2, y + 14, z + 0, 0);
        world.setBlock(x + 2, y + 14, z + 3, 0);
        world.setBlock(x + 2, y + 14, z + 4, Block.stairsWoodOak.blockID, 2, 2);
        world.setBlock(x + 2, y + 14, z + 5, Block.stairsWoodOak.blockID, 7, 2);
        world.setBlock(x + 2, y + 14, z + 6, 0);
        world.setBlock(x + 2, y + 14, z + 7, 0);
        world.setBlock(x + 2, y + 14, z + 8, 0);
        world.setBlock(x + 2, y + 14, z + 9, 0);
        world.setBlock(x + 2, y + 14, z + 10, 0);
        world.setBlock(x + 2, y + 14, z + 11, 0);
        world.setBlock(x + 2, y + 14, z + 12, 0);
        world.setBlock(x + 2, y + 14, z + 13, 0);
        world.setBlock(x + 2, y + 14, z + 14, 0);
        world.setBlock(x + 2, y + 14, z + 15, 0);
        world.setBlock(x + 2, y + 14, z + 16, Block.sandStone.blockID, 2, 2);
        world.setBlock(x + 2, y + 14, z + 17, 0);
        world.setBlock(x + 2, y + 15, z + 0, 0);
        world.setBlock(x + 2, y + 15, z + 2, 0);
        world.setBlock(x + 2, y + 15, z + 3, 0);
        world.setBlock(x + 2, y + 15, z + 4, 0);
        world.setBlock(x + 2, y + 15, z + 5, Block.stairsWoodOak.blockID, 2, 2);
        world.setBlock(x + 2, y + 15, z + 6, Block.stairsWoodOak.blockID, 7, 2);
        world.setBlock(x + 2, y + 15, z + 7, 0);
        world.setBlock(x + 2, y + 15, z + 8, 0);
        world.setBlock(x + 2, y + 15, z + 9, 0);
        world.setBlock(x + 2, y + 15, z + 10, 0);
        world.setBlock(x + 2, y + 15, z + 11, 0);
        world.setBlock(x + 2, y + 15, z + 12, 0);
        world.setBlock(x + 2, y + 15, z + 13, 0);
        world.setBlock(x + 2, y + 15, z + 14, 0);
        world.setBlock(x + 2, y + 15, z + 15, 0);
        world.setBlock(x + 2, y + 15, z + 16, Block.sandStone.blockID, 2, 2);
        world.setBlock(x + 2, y + 15, z + 17, 0);
        world.setBlock(x + 2, y + 16, z + 0, 0);
        world.setBlock(x + 2, y + 16, z + 1, Block.planks.blockID, 2, 2);
        world.setBlock(x + 2, y + 16, z + 2, 0);
        world.setBlock(x + 2, y + 16, z + 3, 0);
        world.setBlock(x + 2, y + 16, z + 4, 0);
        world.setBlock(x + 2, y + 16, z + 5, 0);
        world.setBlock(x + 2, y + 16, z + 6, Block.stairsWoodOak.blockID, 2, 2);
        world.setBlock(x + 2, y + 16, z + 7, Block.planks.blockID, 2, 2);
        world.setBlock(x + 2, y + 16, z + 8, Block.planks.blockID, 2, 2);
        world.setBlock(x + 2, y + 16, z + 9, Block.planks.blockID, 2, 2);
        world.setBlock(x + 2, y + 16, z + 10, Block.planks.blockID, 2, 2);
        world.setBlock(x + 2, y + 16, z + 11, Block.planks.blockID, 2, 2);
        world.setBlock(x + 2, y + 16, z + 12, Block.planks.blockID, 2, 2);
        world.setBlock(x + 2, y + 16, z + 13, Block.planks.blockID, 2, 2);
        world.setBlock(x + 2, y + 16, z + 14, Block.planks.blockID, 2, 2);
        world.setBlock(x + 2, y + 16, z + 15, Block.planks.blockID, 2, 2);
        world.setBlock(x + 2, y + 16, z + 16, Block.sandStone.blockID, 2, 2);
        world.setBlock(x + 2, y + 16, z + 17, 0);
        world.setBlock(x + 2, y + 17, z + 0, 0);
        world.setBlock(x + 2, y + 17, z + 1, Block.planks.blockID, 2, 2);
        world.setBlock(x + 2, y + 17, z + 2, 0);
        world.setBlock(x + 2, y + 17, z + 3, 0);
        world.setBlock(x + 2, y + 17, z + 4, 0);
        world.setBlock(x + 2, y + 17, z + 5, 0);
        world.setBlock(x + 2, y + 17, z + 6, 0);
        world.setBlock(x + 2, y + 17, z + 7, 0);
        world.setBlock(x + 2, y + 17, z + 8, 0);
        world.setBlock(x + 2, y + 17, z + 9, 0);
        world.setBlock(x + 2, y + 17, z + 10, 0);
        world.setBlock(x + 2, y + 17, z + 11, 0);
        world.setBlock(x + 2, y + 17, z + 12, 0);
        world.setBlock(x + 2, y + 17, z + 13, 0);
        world.setBlock(x + 2, y + 17, z + 14, 0);
        world.setBlock(x + 2, y + 17, z + 15, Block.chest.blockID, 2, 2);
        world.setBlock(x + 2, y + 17, z + 16, Block.planks.blockID, 2, 2);
        world.setBlock(x + 2, y + 17, z + 17, 0);
        world.setBlock(x + 2, y + 18, z + 0, 0);
        world.setBlock(x + 2, y + 18, z + 1, Block.planks.blockID, 2, 2);
        world.setBlock(x + 2, y + 18, z + 2, 0);
        world.setBlock(x + 2, y + 18, z + 3, 0);
        world.setBlock(x + 2, y + 18, z + 4, 0);
        world.setBlock(x + 2, y + 18, z + 5, 0);
        world.setBlock(x + 2, y + 18, z + 6, 0);
        world.setBlock(x + 2, y + 18, z + 7, 0);
        world.setBlock(x + 2, y + 18, z + 8, 0);
        world.setBlock(x + 2, y + 18, z + 9, 0);
        world.setBlock(x + 2, y + 18, z + 10, 0);
        world.setBlock(x + 2, y + 18, z + 11, 0);
        world.setBlock(x + 2, y + 18, z + 12, 0);
        world.setBlock(x + 2, y + 18, z + 13, 0);
        world.setBlock(x + 2, y + 18, z + 14, 0);
        world.setBlock(x + 2, y + 18, z + 15, 0);
        world.setBlock(x + 2, y + 18, z + 16, Block.planks.blockID, 2, 2);
        world.setBlock(x + 2, y + 18, z + 17, 0);
        world.setBlock(x + 2, y + 19, z + 0, Block.stairsSandStone.blockID, 2, 2);
        world.setBlock(x + 2, y + 19, z + 1, Block.planks.blockID, 2, 2);
        world.setBlock(x + 2, y + 19, z + 3, 0);
        world.setBlock(x + 2, y + 19, z + 4, 0);
        world.setBlock(x + 2, y + 19, z + 5, 0);
        world.setBlock(x + 2, y + 19, z + 6, 0);
        world.setBlock(x + 2, y + 19, z + 7, 0);
        world.setBlock(x + 2, y + 19, z + 8, 0);
        world.setBlock(x + 2, y + 19, z + 9, 0);
        world.setBlock(x + 2, y + 19, z + 10, 0);
        world.setBlock(x + 2, y + 19, z + 11, 0);
        world.setBlock(x + 2, y + 19, z + 12, 0);
        world.setBlock(x + 2, y + 19, z + 13, 0);
        world.setBlock(x + 2, y + 19, z + 14, 0);
        world.setBlock(x + 2, y + 19, z + 16, Block.planks.blockID, 2, 2);
        world.setBlock(x + 2, y + 19, z + 17, Block.stairsSandStone.blockID, 3, 2);
        world.setBlock(x + 2, y + 20, z + 0, 0);
        world.setBlock(x + 2, y + 20, z + 1, Block.stairsSandStone.blockID, 2, 2);
        world.setBlock(x + 2, y + 20, z + 2, Block.planks.blockID, 2, 2);
        world.setBlock(x + 2, y + 20, z + 3, Block.planks.blockID, 2, 2);
        world.setBlock(x + 2, y + 20, z + 4, Block.planks.blockID, 2, 2);
        world.setBlock(x + 2, y + 20, z + 5, Block.planks.blockID, 2, 2);
        world.setBlock(x + 2, y + 20, z + 6, Block.planks.blockID, 2, 2);
        world.setBlock(x + 2, y + 20, z + 7, Block.planks.blockID, 2, 2);
        world.setBlock(x + 2, y + 20, z + 8, Block.planks.blockID, 2, 2);
        world.setBlock(x + 2, y + 20, z + 9, Block.planks.blockID, 2, 2);
        world.setBlock(x + 2, y + 20, z + 10, Block.planks.blockID, 2, 2);
        world.setBlock(x + 2, y + 20, z + 11, Block.planks.blockID, 2, 2);
        world.setBlock(x + 2, y + 20, z + 12, Block.planks.blockID, 2, 2);
        world.setBlock(x + 2, y + 20, z + 13, Block.planks.blockID, 2, 2);
        world.setBlock(x + 2, y + 20, z + 14, Block.planks.blockID, 2, 2);
        world.setBlock(x + 2, y + 20, z + 15, Block.planks.blockID, 2, 2);
        world.setBlock(x + 2, y + 20, z + 16, Block.stairsSandStone.blockID, 3, 2);
        world.setBlock(x + 2, y + 20, z + 17, 0);
        world.setBlock(x + 2, y + 21, z + 0, 0);
        world.setBlock(x + 2, y + 21, z + 1, 0);
        world.setBlock(x + 2, y + 21, z + 2, Block.stairsSandStone.blockID, 2, 2);
        world.setBlock(x + 2, y + 21, z + 3, Block.stairsSandStone.blockID, 7, 2);
        world.setBlock(x + 2, y + 21, z + 4, 0);
        world.setBlock(x + 2, y + 21, z + 5, 0);
        world.setBlock(x + 2, y + 21, z + 6, 0);
        world.setBlock(x + 2, y + 21, z + 7, 0);
        world.setBlock(x + 2, y + 21, z + 8, 0);
        world.setBlock(x + 2, y + 21, z + 9, 0);
        world.setBlock(x + 2, y + 21, z + 10, 0);
        world.setBlock(x + 2, y + 21, z + 11, 0);
        world.setBlock(x + 2, y + 21, z + 12, 0);
        world.setBlock(x + 2, y + 21, z + 13, Block.web.blockID, 0, 2);
        world.setBlock(x + 2, y + 21, z + 14, Block.stairsSandStone.blockID, 6, 2);
        world.setBlock(x + 2, y + 21, z + 15, Block.stairsSandStone.blockID, 3, 2);
        world.setBlock(x + 2, y + 21, z + 16, 0);
        world.setBlock(x + 2, y + 21, z + 17, 0);
        world.setBlock(x + 2, y + 22, z + 0, 0);
        world.setBlock(x + 2, y + 22, z + 1, 0);
        world.setBlock(x + 2, y + 22, z + 2, 0);
        world.setBlock(x + 2, y + 22, z + 3, Block.stairsSandStone.blockID, 2, 2);
        world.setBlock(x + 2, y + 22, z + 4, Block.stairsSandStone.blockID, 7, 2);
        world.setBlock(x + 2, y + 22, z + 5, 0);
        world.setBlock(x + 2, y + 22, z + 6, 0);
        world.setBlock(x + 2, y + 22, z + 7, 0);
        world.setBlock(x + 2, y + 22, z + 8, 0);
        world.setBlock(x + 2, y + 22, z + 9, 0);
        world.setBlock(x + 2, y + 22, z + 10, 0);
        world.setBlock(x + 2, y + 22, z + 11, 0);
        world.setBlock(x + 2, y + 22, z + 12, 0);
        world.setBlock(x + 2, y + 22, z + 13, Block.stairsSandStone.blockID, 6, 2);
        world.setBlock(x + 2, y + 22, z + 14, Block.stairsSandStone.blockID, 3, 2);
        world.setBlock(x + 2, y + 22, z + 15, 0);
        world.setBlock(x + 2, y + 22, z + 16, 0);
        world.setBlock(x + 2, y + 22, z + 17, 0);
        world.setBlock(x + 2, y + 23, z + 0, 0);
        world.setBlock(x + 2, y + 23, z + 1, 0);
        world.setBlock(x + 2, y + 23, z + 2, 0);
        world.setBlock(x + 2, y + 23, z + 3, 0);
        world.setBlock(x + 2, y + 23, z + 4, Block.stairsSandStone.blockID, 2, 2);
        world.setBlock(x + 2, y + 23, z + 5, Block.stairsSandStone.blockID, 7, 2);
        world.setBlock(x + 2, y + 23, z + 6, 0);
        world.setBlock(x + 2, y + 23, z + 7, 0);
        world.setBlock(x + 2, y + 23, z + 8, 0);
        world.setBlock(x + 2, y + 23, z + 9, 0);
        world.setBlock(x + 2, y + 23, z + 10, 0);
        world.setBlock(x + 2, y + 23, z + 11, 0);
        world.setBlock(x + 2, y + 23, z + 12, Block.stairsSandStone.blockID, 6, 2);
        world.setBlock(x + 2, y + 23, z + 13, Block.stairsSandStone.blockID, 3, 2);
        world.setBlock(x + 2, y + 23, z + 14, 0);
        world.setBlock(x + 2, y + 23, z + 15, 0);
        world.setBlock(x + 2, y + 23, z + 16, 0);
        world.setBlock(x + 2, y + 23, z + 17, 0);
        world.setBlock(x + 2, y + 24, z + 0, 0);
        world.setBlock(x + 2, y + 24, z + 1, 0);
        world.setBlock(x + 2, y + 24, z + 2, 0);
        world.setBlock(x + 2, y + 24, z + 3, 0);
        world.setBlock(x + 2, y + 24, z + 4, 0);
        world.setBlock(x + 2, y + 24, z + 5, Block.stairsSandStone.blockID, 2, 2);
        world.setBlock(x + 2, y + 24, z + 6, Block.stairsSandStone.blockID, 7, 2);
        world.setBlock(x + 2, y + 24, z + 7, 0);
        world.setBlock(x + 2, y + 24, z + 8, 0);
        world.setBlock(x + 2, y + 24, z + 9, 0);
        world.setBlock(x + 2, y + 24, z + 10, 0);
        world.setBlock(x + 2, y + 24, z + 11, Block.stairsSandStone.blockID, 6, 2);
        world.setBlock(x + 2, y + 24, z + 12, Block.stairsSandStone.blockID, 3, 2);
        world.setBlock(x + 2, y + 24, z + 13, 0);
        world.setBlock(x + 2, y + 24, z + 14, 0);
        world.setBlock(x + 2, y + 24, z + 15, 0);
        world.setBlock(x + 2, y + 24, z + 16, 0);
        world.setBlock(x + 2, y + 24, z + 17, 0);
        world.setBlock(x + 2, y + 25, z + 0, 0);
        world.setBlock(x + 2, y + 25, z + 1, 0);
        world.setBlock(x + 2, y + 25, z + 2, 0);
        world.setBlock(x + 2, y + 25, z + 3, 0);
        world.setBlock(x + 2, y + 25, z + 4, 0);
        world.setBlock(x + 2, y + 25, z + 5, 0);
        world.setBlock(x + 2, y + 25, z + 6, Block.stoneSingleSlab.blockID, 1, 2);
        world.setBlock(x + 2, y + 25, z + 7, Block.stoneSingleSlab.blockID, 1, 2);
        world.setBlock(x + 2, y + 25, z + 8, Block.stoneSingleSlab.blockID, 1, 2);
        world.setBlock(x + 2, y + 25, z + 9, Block.stoneSingleSlab.blockID, 1, 2);
        world.setBlock(x + 2, y + 25, z + 10, Block.stoneSingleSlab.blockID, 1, 2);
        world.setBlock(x + 2, y + 25, z + 11, Block.stoneSingleSlab.blockID, 1, 2);
        world.setBlock(x + 2, y + 25, z + 12, 0);
        world.setBlock(x + 2, y + 25, z + 13, 0);
        world.setBlock(x + 2, y + 25, z + 14, 0);
        world.setBlock(x + 2, y + 25, z + 15, 0);
        world.setBlock(x + 2, y + 25, z + 16, 0);
        world.setBlock(x + 2, y + 25, z + 17, 0);
        world.setBlock(x + 3, y + 0, z + 1, Block.sandStone.blockID, 2, 2);
        world.setBlock(x + 3, y + 0, z + 2, Block.stone.blockID, 0, 2);
        world.setBlock(x + 3, y + 0, z + 3, Block.stainedClay.blockID, 9, 2);
        world.setBlock(x + 3, y + 0, z + 4, Block.stainedClay.blockID, 9, 2);
        world.setBlock(x + 3, y + 0, z + 5, Block.stainedClay.blockID, 9, 2);
        world.setBlock(x + 3, y + 0, z + 6, Block.stainedClay.blockID, 9, 2);
        world.setBlock(x + 3, y + 0, z + 7, Block.stainedClay.blockID, 9, 2);
        world.setBlock(x + 3, y + 0, z + 8, Block.stainedClay.blockID, 9, 2);
        world.setBlock(x + 3, y + 0, z + 9, Block.stainedClay.blockID, 9, 2);
        world.setBlock(x + 3, y + 0, z + 10, Block.stainedClay.blockID, 9, 2);
        world.setBlock(x + 3, y + 0, z + 11, Block.stainedClay.blockID, 9, 2);
        world.setBlock(x + 3, y + 0, z + 12, Block.stainedClay.blockID, 9, 2);
        world.setBlock(x + 3, y + 0, z + 13, Block.stainedClay.blockID, 9, 2);
        world.setBlock(x + 3, y + 0, z + 14, Block.stainedClay.blockID, 9, 2);
        world.setBlock(x + 3, y + 0, z + 15, Block.stainedClay.blockID, 9, 2);
        world.setBlock(x + 3, y + 0, z + 16, Block.sandStone.blockID, 2, 2);
        world.setBlock(x + 3, y + 1, z + 1, Block.sandStone.blockID, 2, 2);
        world.setBlock(x + 3, y + 1, z + 2, Block.sandStone.blockID, 2, 2);
        world.setBlock(x + 3, y + 1, z + 3, 0);
        world.setBlock(x + 3, y + 1, z + 4, 0);
        world.setBlock(x + 3, y + 1, z + 5, 0);
        world.setBlock(x + 3, y + 1, z + 6, 0);
        world.setBlock(x + 3, y + 1, z + 7, 0);
        world.setBlock(x + 3, y + 1, z + 8, 0);
        world.setBlock(x + 3, y + 1, z + 9, 0);
        world.setBlock(x + 3, y + 1, z + 10, 0);
        world.setBlock(x + 3, y + 1, z + 11, 0);
        world.setBlock(x + 3, y + 1, z + 12, 0);
        world.setBlock(x + 3, y + 1, z + 13, 0);
        world.setBlock(x + 3, y + 1, z + 14, 0);
        world.setBlock(x + 3, y + 1, z + 15, 0);
        world.setBlock(x + 3, y + 1, z + 16, Block.sandStone.blockID, 2, 2);
        world.setBlock(x + 3, y + 2, z + 1, Block.sandStone.blockID, 2, 2);
        world.setBlock(x + 3, y + 2, z + 2, Block.sandStone.blockID, 2, 2);
        world.setBlock(x + 3, y + 2, z + 3, 0);
        world.setBlock(x + 3, y + 2, z + 4, 0);
        world.setBlock(x + 3, y + 2, z + 5, 0);
        world.setBlock(x + 3, y + 2, z + 6, 0);
        world.setBlock(x + 3, y + 2, z + 7, 0);
        world.setBlock(x + 3, y + 2, z + 8, 0);
        world.setBlock(x + 3, y + 2, z + 9, 0);
        world.setBlock(x + 3, y + 2, z + 10, 0);
        world.setBlock(x + 3, y + 2, z + 11, 0);
        world.setBlock(x + 3, y + 2, z + 12, 0);
        world.setBlock(x + 3, y + 2, z + 13, 0);
        world.setBlock(x + 3, y + 2, z + 14, 0);
        world.setBlock(x + 3, y + 2, z + 15, 0);
        world.setBlock(x + 3, y + 2, z + 16, Block.sandStone.blockID, 2, 2);
        world.setBlock(x + 3, y + 3, z + 1, Block.sandStone.blockID, 2, 2);
        world.setBlock(x + 3, y + 3, z + 2, Block.sandStone.blockID, 2, 2);
        world.setBlock(x + 3, y + 3, z + 3, 0);
        world.setBlock(x + 3, y + 3, z + 4, 0);
        world.setBlock(x + 3, y + 3, z + 5, 0);
        world.setBlock(x + 3, y + 3, z + 6, 0);
        world.setBlock(x + 3, y + 3, z + 7, 0);
        world.setBlock(x + 3, y + 3, z + 8, 0);
        world.setBlock(x + 3, y + 3, z + 9, 0);
        world.setBlock(x + 3, y + 3, z + 10, 0);
        world.setBlock(x + 3, y + 3, z + 11, 0);
        world.setBlock(x + 3, y + 3, z + 12, 0);
        world.setBlock(x + 3, y + 3, z + 13, 0);
        world.setBlock(x + 3, y + 3, z + 14, 0);
        world.setBlock(x + 3, y + 3, z + 15, 0);
        world.setBlock(x + 3, y + 3, z + 16, Block.sandStone.blockID, 2, 2);
        world.setBlock(x + 3, y + 4, z + 1, Block.sandStone.blockID, 2, 2);
        world.setBlock(x + 3, y + 4, z + 2, Block.sandStone.blockID, 2, 2);
        world.setBlock(x + 3, y + 4, z + 3, Block.glass.blockID, 0, 2);
        world.setBlock(x + 3, y + 4, z + 4, Block.glass.blockID, 0, 2);
        world.setBlock(x + 3, y + 4, z + 5, Block.glass.blockID, 0, 2);
        world.setBlock(x + 3, y + 4, z + 6, Block.glass.blockID, 0, 2);
        world.setBlock(x + 3, y + 4, z + 7, Block.glass.blockID, 0, 2);
        world.setBlock(x + 3, y + 4, z + 8, Block.glass.blockID, 0, 2);
        world.setBlock(x + 3, y + 4, z + 9, Block.glass.blockID, 0, 2);
        world.setBlock(x + 3, y + 4, z + 10, Block.glass.blockID, 0, 2);
        world.setBlock(x + 3, y + 4, z + 11, Block.glass.blockID, 0, 2);
        world.setBlock(x + 3, y + 4, z + 12, Block.glass.blockID, 0, 2);
        world.setBlock(x + 3, y + 4, z + 13, Block.glass.blockID, 0, 2);
        world.setBlock(x + 3, y + 4, z + 14, Block.glass.blockID, 0, 2);
        world.setBlock(x + 3, y + 4, z + 15, Block.glass.blockID, 0, 2);
        world.setBlock(x + 3, y + 4, z + 16, Block.sandStone.blockID, 2, 2);
        world.setBlock(x + 3, y + 5, z + 1, Block.sandStone.blockID, 2, 2);
        world.setBlock(x + 3, y + 5, z + 2, Block.sandStone.blockID, 2, 2);
        world.setBlock(x + 3, y + 5, z + 3, 0);
        world.setBlock(x + 3, y + 5, z + 4, 0);
        world.setBlock(x + 3, y + 5, z + 5, 0);
        world.setBlock(x + 3, y + 5, z + 6, 0);
        world.setBlock(x + 3, y + 5, z + 7, 0);
        world.setBlock(x + 3, y + 5, z + 8, 0);
        world.setBlock(x + 3, y + 5, z + 9, 0);
        world.setBlock(x + 3, y + 5, z + 10, 0);
        world.setBlock(x + 3, y + 5, z + 11, 0);
        world.setBlock(x + 3, y + 5, z + 12, 0);
        world.setBlock(x + 3, y + 5, z + 13, 0);
        world.setBlock(x + 3, y + 5, z + 14, 0);
        world.setBlock(x + 3, y + 5, z + 15, 0);
        world.setBlock(x + 3, y + 5, z + 16, Block.sandStone.blockID, 2, 2);
        world.setBlock(x + 3, y + 6, z + 1, Block.sandStone.blockID, 2, 2);
        world.setBlock(x + 3, y + 6, z + 2, Block.sandStone.blockID, 2, 2);
        world.setBlock(x + 3, y + 6, z + 3, Block.stairsWoodOak.blockID, 4, 2);
        world.setBlock(x + 3, y + 6, z + 4, Block.stairsWoodOak.blockID, 4, 2);
        world.setBlock(x + 3, y + 6, z + 5, 0);
        world.setBlock(x + 3, y + 6, z + 6, 0);
        world.setBlock(x + 3, y + 6, z + 7, 0);
        world.setBlock(x + 3, y + 6, z + 8, 0);
        world.setBlock(x + 3, y + 6, z + 9, 0);
        world.setBlock(x + 3, y + 6, z + 10, 0);
        world.setBlock(x + 3, y + 6, z + 11, 0);
        world.setBlock(x + 3, y + 6, z + 12, 0);
        world.setBlock(x + 3, y + 6, z + 13, 0);
        world.setBlock(x + 3, y + 6, z + 14, 0);
        world.setBlock(x + 3, y + 6, z + 15, 0);
        world.setBlock(x + 3, y + 6, z + 16, Block.sandStone.blockID, 2, 2);
        world.setBlock(x + 3, y + 7, z + 1, Block.sandStone.blockID, 2, 2);
        world.setBlock(x + 3, y + 7, z + 2, Block.sandStone.blockID, 2, 2);
        world.setBlock(x + 3, y + 7, z + 3, Block.stairsWoodOak.blockID, 1, 2);
        world.setBlock(x + 3, y + 7, z + 4, Block.stairsWoodOak.blockID, 1, 2);
        world.setBlock(x + 3, y + 7, z + 5, 0);
        world.setBlock(x + 3, y + 7, z + 6, 0);
        world.setBlock(x + 3, y + 7, z + 7, 0);
        world.setBlock(x + 3, y + 7, z + 8, 0);
        world.setBlock(x + 3, y + 7, z + 9, 0);
        world.setBlock(x + 3, y + 7, z + 10, 0);
        world.setBlock(x + 3, y + 7, z + 11, 0);
        world.setBlock(x + 3, y + 7, z + 12, 0);
        world.setBlock(x + 3, y + 7, z + 13, 0);
        world.setBlock(x + 3, y + 7, z + 14, 0);
        world.setBlock(x + 3, y + 7, z + 15, 0);
        world.setBlock(x + 3, y + 7, z + 16, Block.sandStone.blockID, 2, 2);
        world.setBlock(x + 3, y + 8, z + 1, Block.sandStone.blockID, 2, 2);
        world.setBlock(x + 3, y + 8, z + 2, Block.planks.blockID, 2, 2);
        world.setBlock(x + 3, y + 8, z + 3, 0);
        world.setBlock(x + 3, y + 8, z + 4, 0);
        world.setBlock(x + 3, y + 8, z + 5, 0);
        world.setBlock(x + 3, y + 8, z + 6, 0);
        world.setBlock(x + 3, y + 8, z + 7, 0);
        world.setBlock(x + 3, y + 8, z + 8, 0);
        world.setBlock(x + 3, y + 8, z + 9, 0);
        world.setBlock(x + 3, y + 8, z + 10, 0);
        world.setBlock(x + 3, y + 8, z + 11, 0);
        world.setBlock(x + 3, y + 8, z + 12, 0);
        world.setBlock(x + 3, y + 8, z + 13, 0);
        world.setBlock(x + 3, y + 8, z + 14, 0);
        world.setBlock(x + 3, y + 8, z + 15, 0);
        world.setBlock(x + 3, y + 8, z + 16, Block.sandStone.blockID, 2, 2);
        world.setBlock(x + 3, y + 9, z + 1, Block.sandStone.blockID, 2, 2);
        world.setBlock(x + 3, y + 9, z + 2, Block.pumpkinLantern.blockID, 0, 2);
        world.setBlock(x + 3, y + 9, z + 3, 0);
        world.setBlock(x + 3, y + 9, z + 4, 0);
        world.setBlock(x + 3, y + 9, z + 5, Block.planks.blockID, 2, 2);
        world.setBlock(x + 3, y + 9, z + 6, Block.planks.blockID, 2, 2);
        world.setBlock(x + 3, y + 9, z + 7, Block.planks.blockID, 2, 2);
        world.setBlock(x + 3, y + 9, z + 8, Block.planks.blockID, 2, 2);
        world.setBlock(x + 3, y + 9, z + 9, Block.planks.blockID, 2, 2);
        world.setBlock(x + 3, y + 9, z + 10, Block.planks.blockID, 2, 2);
        world.setBlock(x + 3, y + 9, z + 11, Block.planks.blockID, 2, 2);
        world.setBlock(x + 3, y + 9, z + 12, Block.planks.blockID, 2, 2);
        world.setBlock(x + 3, y + 9, z + 13, Block.planks.blockID, 2, 2);
        world.setBlock(x + 3, y + 9, z + 14, Block.planks.blockID, 2, 2);
        world.setBlock(x + 3, y + 9, z + 15, Block.planks.blockID, 2, 2);
        world.setBlock(x + 3, y + 9, z + 16, Block.sandStone.blockID, 2, 2);
        world.setBlock(x + 3, y + 10, z + 1, Block.planks.blockID, 2, 2);
        world.setBlock(x + 3, y + 10, z + 2, 0);
        world.setBlock(x + 3, y + 10, z + 3, 0);
        world.setBlock(x + 3, y + 10, z + 4, 0);
        world.setBlock(x + 3, y + 10, z + 5, 0);
        world.setBlock(x + 3, y + 10, z + 6, 0);
        world.setBlock(x + 3, y + 10, z + 7, Block.stoneDoubleSlab.blockID, 0, 2);
        world.setBlock(x + 3, y + 10, z + 8, Block.stoneSingleSlab.blockID, 8, 2);
        world.setBlock(x + 3, y + 10, z + 9, Block.stoneSingleSlab.blockID, 8, 2);
        world.setBlock(x + 3, y + 10, z + 10, Block.stoneSingleSlab.blockID, 8, 2);
        world.setBlock(x + 3, y + 10, z + 11, Block.stoneDoubleSlab.blockID, 0, 2);
        world.setBlock(x + 3, y + 10, z + 14, Block.stoneDoubleSlab.blockID, 0, 2);
        world.setBlock(x + 3, y + 10, z + 15, Block.stoneSingleSlab.blockID, 8, 2);
        world.setBlock(x + 3, y + 10, z + 16, Block.planks.blockID, 2, 2);
        world.setBlock(x + 3, y + 11, z + 1, Block.planks.blockID, 2, 2);
        world.setBlock(x + 3, y + 11, z + 2, 0);
        world.setBlock(x + 3, y + 11, z + 3, 0);
        world.setBlock(x + 3, y + 11, z + 4, 0);
        world.setBlock(x + 3, y + 11, z + 5, 0);
        world.setBlock(x + 3, y + 11, z + 6, 0);
        world.setBlock(x + 3, y + 11, z + 7, 0);
        world.setBlock(x + 3, y + 11, z + 8, 0);
        world.setBlock(x + 3, y + 11, z + 9, 0);
        world.setBlock(x + 3, y + 11, z + 10, 0);
        world.setBlock(x + 3, y + 11, z + 11, 0);
        world.setBlock(x + 3, y + 11, z + 12, 0);
        world.setBlock(x + 3, y + 11, z + 13, 0);
        world.setBlock(x + 3, y + 11, z + 14, 0);
        world.setBlock(x + 3, y + 11, z + 15, 0);
        world.setBlock(x + 3, y + 11, z + 16, Block.planks.blockID, 2, 2);
        world.setBlock(x + 3, y + 12, z + 1, Block.planks.blockID, 2, 2);
        world.setBlock(x + 3, y + 12, z + 2, 0);
        world.setBlock(x + 3, y + 12, z + 3, 0);
        world.setBlock(x + 3, y + 12, z + 4, 0);
        world.setBlock(x + 3, y + 12, z + 5, 0);
        world.setBlock(x + 3, y + 12, z + 6, 0);
        world.setBlock(x + 3, y + 12, z + 7, 0);
        world.setBlock(x + 3, y + 12, z + 8, 0);

        generate2(world, rand, x, y, z);
        return true;
    }

    public boolean generate2(World world, Random rand, int x, int y, int z) {
        world.setBlock(x + 3, y + 12, z + 9, 0);
        world.setBlock(x + 3, y + 12, z + 10, 0);
        world.setBlock(x + 3, y + 12, z + 11, 0);
        world.setBlock(x + 3, y + 12, z + 12, 0);
        world.setBlock(x + 3, y + 12, z + 13, 0);
        world.setBlock(x + 3, y + 12, z + 14, 0);
        world.setBlock(x + 3, y + 12, z + 15, 0);
        world.setBlock(x + 3, y + 12, z + 16, Block.planks.blockID, 2, 2);
        world.setBlock(x + 3, y + 13, z + 1, Block.planks.blockID, 2, 2);
        world.setBlock(x + 3, y + 13, z + 2, Block.woodDoubleSlab.blockID, 0, 2);
        world.setBlock(x + 3, y + 13, z + 3, Block.woodDoubleSlab.blockID, 0, 2);
        world.setBlock(x + 3, y + 13, z + 4, Block.stairsWoodOak.blockID, 7, 2);
        world.setBlock(x + 3, y + 13, z + 5, 0);
        world.setBlock(x + 3, y + 13, z + 6, 0);
        world.setBlock(x + 3, y + 13, z + 7, 0);
        world.setBlock(x + 3, y + 13, z + 8, 0);
        world.setBlock(x + 3, y + 13, z + 9, 0);
        world.setBlock(x + 3, y + 13, z + 10, 0);
        world.setBlock(x + 3, y + 13, z + 11, 0);
        world.setBlock(x + 3, y + 13, z + 12, 0);
        world.setBlock(x + 3, y + 13, z + 13, 0);
        world.setBlock(x + 3, y + 13, z + 14, 0);
        world.setBlock(x + 3, y + 13, z + 15, 0);
        world.setBlock(x + 3, y + 13, z + 16, Block.planks.blockID, 2, 2);
        world.setBlock(x + 3, y + 14, z + 0, 0);
        world.setBlock(x + 3, y + 14, z + 3, 0);
        world.setBlock(x + 3, y + 14, z + 4, Block.stairsWoodOak.blockID, 2, 2);
        world.setBlock(x + 3, y + 14, z + 5, Block.stairsWoodOak.blockID, 7, 2);
        world.setBlock(x + 3, y + 14, z + 6, 0);
        world.setBlock(x + 3, y + 14, z + 7, 0);
        world.setBlock(x + 3, y + 14, z + 8, 0);
        world.setBlock(x + 3, y + 14, z + 9, 0);
        world.setBlock(x + 3, y + 14, z + 10, 0);
        world.setBlock(x + 3, y + 14, z + 11, 0);
        world.setBlock(x + 3, y + 14, z + 12, 0);
        world.setBlock(x + 3, y + 14, z + 13, 0);
        world.setBlock(x + 3, y + 14, z + 14, 0);
        world.setBlock(x + 3, y + 14, z + 15, 0);
        world.setBlock(x + 3, y + 14, z + 16, Block.sandStone.blockID, 2, 2);
        world.setBlock(x + 3, y + 14, z + 17, 0);
        world.setBlock(x + 3, y + 15, z + 0, 0);
        world.setBlock(x + 3, y + 15, z + 2, 0);
        world.setBlock(x + 3, y + 15, z + 3, 0);
        world.setBlock(x + 3, y + 15, z + 4, 0);
        world.setBlock(x + 3, y + 15, z + 5, Block.stairsWoodOak.blockID, 2, 2);
        world.setBlock(x + 3, y + 15, z + 6, Block.stairsWoodOak.blockID, 7, 2);
        world.setBlock(x + 3, y + 15, z + 7, 0);
        world.setBlock(x + 3, y + 15, z + 8, 0);
        world.setBlock(x + 3, y + 15, z + 9, 0);
        world.setBlock(x + 3, y + 15, z + 10, 0);
        world.setBlock(x + 3, y + 15, z + 11, 0);
        world.setBlock(x + 3, y + 15, z + 12, 0);
        world.setBlock(x + 3, y + 15, z + 13, 0);
        world.setBlock(x + 3, y + 15, z + 14, 0);
        world.setBlock(x + 3, y + 15, z + 15, 0);
        world.setBlock(x + 3, y + 15, z + 16, Block.sandStone.blockID, 2, 2);
        world.setBlock(x + 3, y + 15, z + 17, 0);
        world.setBlock(x + 3, y + 16, z + 0, 0);
        world.setBlock(x + 3, y + 16, z + 1, Block.planks.blockID, 2, 2);
        world.setBlock(x + 3, y + 16, z + 2, 0);
        world.setBlock(x + 3, y + 16, z + 3, 0);
        world.setBlock(x + 3, y + 16, z + 4, 0);
        world.setBlock(x + 3, y + 16, z + 5, 0);
        world.setBlock(x + 3, y + 16, z + 6, Block.stairsWoodOak.blockID, 2, 2);
        world.setBlock(x + 3, y + 16, z + 7, Block.planks.blockID, 2, 2);
        world.setBlock(x + 3, y + 16, z + 8, Block.planks.blockID, 2, 2);
        world.setBlock(x + 3, y + 16, z + 9, Block.planks.blockID, 2, 2);
        world.setBlock(x + 3, y + 16, z + 10, Block.planks.blockID, 2, 2);
        world.setBlock(x + 3, y + 16, z + 11, Block.planks.blockID, 2, 2);
